[2023-11-11T03:25:19.604+0000] {taskinstance.py:1159} INFO - Dependencies all met for dep_context=non-requeueable deps ti=<TaskInstance: preprocessing_v1.split_task scheduled__2023-11-08T00:00:00+00:00 [queued]>
[2023-11-11T03:25:19.610+0000] {taskinstance.py:1159} INFO - Dependencies all met for dep_context=requeueable deps ti=<TaskInstance: preprocessing_v1.split_task scheduled__2023-11-08T00:00:00+00:00 [queued]>
[2023-11-11T03:25:19.610+0000] {taskinstance.py:1361} INFO - Starting attempt 1 of 6
[2023-11-11T03:25:19.618+0000] {taskinstance.py:1382} INFO - Executing <Task(PythonOperator): split_task> on 2023-11-08 00:00:00+00:00
[2023-11-11T03:25:19.624+0000] {standard_task_runner.py:57} INFO - Started process 236 to run task
[2023-11-11T03:25:19.628+0000] {standard_task_runner.py:84} INFO - Running: ['***', 'tasks', 'run', 'preprocessing_v1', 'split_task', 'scheduled__2023-11-08T00:00:00+00:00', '--job-id', '6', '--raw', '--subdir', 'DAGS_FOLDER/***_code.py', '--cfg-path', '/tmp/tmp13y_jop3']
[2023-11-11T03:25:19.631+0000] {standard_task_runner.py:85} INFO - Job 6: Subtask split_task
[2023-11-11T03:25:19.679+0000] {task_command.py:416} INFO - Running <TaskInstance: preprocessing_v1.split_task scheduled__2023-11-08T00:00:00+00:00 [running]> on host d2c761eebca3
[2023-11-11T03:25:19.743+0000] {taskinstance.py:1662} INFO - Exporting env vars: AIRFLOW_CTX_DAG_OWNER='Team 3' AIRFLOW_CTX_DAG_ID='preprocessing_v1' AIRFLOW_CTX_TASK_ID='split_task' AIRFLOW_CTX_EXECUTION_DATE='2023-11-08T00:00:00+00:00' AIRFLOW_CTX_TRY_NUMBER='1' AIRFLOW_CTX_DAG_RUN_ID='scheduled__2023-11-08T00:00:00+00:00'
[2023-11-11T03:25:21.666+0000] {python.py:194} INFO - Done. Returned value was: 1
[2023-11-11T03:25:21.685+0000] {taskinstance.py:1400} INFO - Marking task as SUCCESS. dag_id=preprocessing_v1, task_id=split_task, execution_date=20231108T000000, start_date=20231111T032519, end_date=20231111T032521
[2023-11-11T03:25:21.714+0000] {local_task_job_runner.py:228} INFO - Task exited with return code 0
[2023-11-11T03:25:21.730+0000] {taskinstance.py:2778} INFO - 1 downstream tasks scheduled from follow-on schedule check
[2023-11-11T03:29:36.811+0000] {taskinstance.py:1159} INFO - Dependencies all met for dep_context=non-requeueable deps ti=<TaskInstance: preprocessing_v1.split_task scheduled__2023-11-08T00:00:00+00:00 [queued]>
[2023-11-11T03:29:36.820+0000] {taskinstance.py:1159} INFO - Dependencies all met for dep_context=requeueable deps ti=<TaskInstance: preprocessing_v1.split_task scheduled__2023-11-08T00:00:00+00:00 [queued]>
[2023-11-11T03:29:36.821+0000] {taskinstance.py:1361} INFO - Starting attempt 1 of 6
[2023-11-11T03:29:36.833+0000] {taskinstance.py:1382} INFO - Executing <Task(PythonOperator): split_task> on 2023-11-08 00:00:00+00:00
[2023-11-11T03:29:36.840+0000] {standard_task_runner.py:57} INFO - Started process 252 to run task
[2023-11-11T03:29:36.844+0000] {standard_task_runner.py:84} INFO - Running: ['***', 'tasks', 'run', 'preprocessing_v1', 'split_task', 'scheduled__2023-11-08T00:00:00+00:00', '--job-id', '4', '--raw', '--subdir', 'DAGS_FOLDER/***_code.py', '--cfg-path', '/tmp/tmppio_z__8']
[2023-11-11T03:29:36.847+0000] {standard_task_runner.py:85} INFO - Job 4: Subtask split_task
[2023-11-11T03:29:36.901+0000] {task_command.py:416} INFO - Running <TaskInstance: preprocessing_v1.split_task scheduled__2023-11-08T00:00:00+00:00 [running]> on host 9c8a8ec1a519
[2023-11-11T03:29:36.963+0000] {taskinstance.py:1662} INFO - Exporting env vars: AIRFLOW_CTX_DAG_OWNER='Team 3' AIRFLOW_CTX_DAG_ID='preprocessing_v1' AIRFLOW_CTX_TASK_ID='split_task' AIRFLOW_CTX_EXECUTION_DATE='2023-11-08T00:00:00+00:00' AIRFLOW_CTX_TRY_NUMBER='1' AIRFLOW_CTX_DAG_RUN_ID='scheduled__2023-11-08T00:00:00+00:00'
[2023-11-11T03:29:38.784+0000] {python.py:194} INFO - Done. Returned value was: 1
[2023-11-11T03:29:38.799+0000] {taskinstance.py:1400} INFO - Marking task as SUCCESS. dag_id=preprocessing_v1, task_id=split_task, execution_date=20231108T000000, start_date=20231111T032936, end_date=20231111T032938
[2023-11-11T03:29:38.821+0000] {local_task_job_runner.py:228} INFO - Task exited with return code 0
[2023-11-11T03:29:38.837+0000] {taskinstance.py:2778} INFO - 1 downstream tasks scheduled from follow-on schedule check
[2023-11-11T03:41:55.286+0000] {taskinstance.py:1159} INFO - Dependencies all met for dep_context=non-requeueable deps ti=<TaskInstance: preprocessing_v1.split_task scheduled__2023-11-08T00:00:00+00:00 [queued]>
[2023-11-11T03:41:55.292+0000] {taskinstance.py:1159} INFO - Dependencies all met for dep_context=requeueable deps ti=<TaskInstance: preprocessing_v1.split_task scheduled__2023-11-08T00:00:00+00:00 [queued]>
[2023-11-11T03:41:55.293+0000] {taskinstance.py:1361} INFO - Starting attempt 1 of 6
[2023-11-11T03:41:55.300+0000] {taskinstance.py:1382} INFO - Executing <Task(PythonOperator): split_task> on 2023-11-08 00:00:00+00:00
[2023-11-11T03:41:55.310+0000] {standard_task_runner.py:57} INFO - Started process 231 to run task
[2023-11-11T03:41:55.329+0000] {standard_task_runner.py:84} INFO - Running: ['***', 'tasks', 'run', 'preprocessing_v1', 'split_task', 'scheduled__2023-11-08T00:00:00+00:00', '--job-id', '4', '--raw', '--subdir', 'DAGS_FOLDER/***_code.py', '--cfg-path', '/tmp/tmpeh32yh1f']
[2023-11-11T03:41:55.332+0000] {standard_task_runner.py:85} INFO - Job 4: Subtask split_task
[2023-11-11T03:41:55.403+0000] {task_command.py:416} INFO - Running <TaskInstance: preprocessing_v1.split_task scheduled__2023-11-08T00:00:00+00:00 [running]> on host 27df91229c7e
[2023-11-11T03:41:55.458+0000] {taskinstance.py:1662} INFO - Exporting env vars: AIRFLOW_CTX_DAG_OWNER='Team 3' AIRFLOW_CTX_DAG_ID='preprocessing_v1' AIRFLOW_CTX_TASK_ID='split_task' AIRFLOW_CTX_EXECUTION_DATE='2023-11-08T00:00:00+00:00' AIRFLOW_CTX_TRY_NUMBER='1' AIRFLOW_CTX_DAG_RUN_ID='scheduled__2023-11-08T00:00:00+00:00'
[2023-11-11T03:41:55.459+0000] {datapreprocessing.py:40} INFO - Splitting dataset...
[2023-11-11T03:41:57.410+0000] {datapreprocessing.py:52} INFO - Dataset split.
[2023-11-11T03:41:57.414+0000] {python.py:194} INFO - Done. Returned value was: 1
[2023-11-11T03:41:57.429+0000] {taskinstance.py:1400} INFO - Marking task as SUCCESS. dag_id=preprocessing_v1, task_id=split_task, execution_date=20231108T000000, start_date=20231111T034155, end_date=20231111T034157
[2023-11-11T03:41:57.469+0000] {local_task_job_runner.py:228} INFO - Task exited with return code 0
[2023-11-11T03:41:57.491+0000] {taskinstance.py:2778} INFO - 1 downstream tasks scheduled from follow-on schedule check
[2023-11-11T04:44:18.637+0000] {taskinstance.py:1159} INFO - Dependencies all met for dep_context=non-requeueable deps ti=<TaskInstance: preprocessing_v1.split_task scheduled__2023-11-08T00:00:00+00:00 [queued]>
[2023-11-11T04:44:18.643+0000] {taskinstance.py:1159} INFO - Dependencies all met for dep_context=requeueable deps ti=<TaskInstance: preprocessing_v1.split_task scheduled__2023-11-08T00:00:00+00:00 [queued]>
[2023-11-11T04:44:18.643+0000] {taskinstance.py:1361} INFO - Starting attempt 1 of 6
[2023-11-11T04:44:18.651+0000] {taskinstance.py:1382} INFO - Executing <Task(PythonOperator): split_task> on 2023-11-08 00:00:00+00:00
[2023-11-11T04:44:18.659+0000] {standard_task_runner.py:57} INFO - Started process 232 to run task
[2023-11-11T04:44:18.664+0000] {standard_task_runner.py:84} INFO - Running: ['***', 'tasks', 'run', 'preprocessing_v1', 'split_task', 'scheduled__2023-11-08T00:00:00+00:00', '--job-id', '6', '--raw', '--subdir', 'DAGS_FOLDER/***_code.py', '--cfg-path', '/tmp/tmphvfrvyh6']
[2023-11-11T04:44:18.668+0000] {standard_task_runner.py:85} INFO - Job 6: Subtask split_task
[2023-11-11T04:44:18.726+0000] {task_command.py:416} INFO - Running <TaskInstance: preprocessing_v1.split_task scheduled__2023-11-08T00:00:00+00:00 [running]> on host bb20688940fc
[2023-11-11T04:44:18.785+0000] {taskinstance.py:1662} INFO - Exporting env vars: AIRFLOW_CTX_DAG_OWNER='Team 3' AIRFLOW_CTX_DAG_ID='preprocessing_v1' AIRFLOW_CTX_TASK_ID='split_task' AIRFLOW_CTX_EXECUTION_DATE='2023-11-08T00:00:00+00:00' AIRFLOW_CTX_TRY_NUMBER='1' AIRFLOW_CTX_DAG_RUN_ID='scheduled__2023-11-08T00:00:00+00:00'
[2023-11-11T04:44:18.786+0000] {datapreprocessing.py:39} INFO - Splitting dataset...
[2023-11-11T04:44:20.996+0000] {datapreprocessing.py:51} INFO - Dataset split.
[2023-11-11T04:44:21.001+0000] {python.py:194} INFO - Done. Returned value was: 1
[2023-11-11T04:44:21.030+0000] {taskinstance.py:1400} INFO - Marking task as SUCCESS. dag_id=preprocessing_v1, task_id=split_task, execution_date=20231108T000000, start_date=20231111T044418, end_date=20231111T044421
[2023-11-11T04:44:21.069+0000] {local_task_job_runner.py:228} INFO - Task exited with return code 0
[2023-11-11T04:44:21.104+0000] {taskinstance.py:2778} INFO - 1 downstream tasks scheduled from follow-on schedule check
[2023-11-11T07:08:25.495+0000] {taskinstance.py:1159} INFO - Dependencies all met for dep_context=non-requeueable deps ti=<TaskInstance: preprocessing_v1.split_task scheduled__2023-11-08T00:00:00+00:00 [queued]>
[2023-11-11T07:08:25.511+0000] {taskinstance.py:1159} INFO - Dependencies all met for dep_context=requeueable deps ti=<TaskInstance: preprocessing_v1.split_task scheduled__2023-11-08T00:00:00+00:00 [queued]>
[2023-11-11T07:08:25.512+0000] {taskinstance.py:1361} INFO - Starting attempt 1 of 6
[2023-11-11T07:08:25.533+0000] {taskinstance.py:1382} INFO - Executing <Task(PythonOperator): split_task> on 2023-11-08 00:00:00+00:00
[2023-11-11T07:08:25.573+0000] {standard_task_runner.py:57} INFO - Started process 253 to run task
[2023-11-11T07:08:25.603+0000] {standard_task_runner.py:84} INFO - Running: ['***', 'tasks', 'run', 'preprocessing_v1', 'split_task', 'scheduled__2023-11-08T00:00:00+00:00', '--job-id', '3', '--raw', '--subdir', 'DAGS_FOLDER/***_code.py', '--cfg-path', '/tmp/tmp5nrmskw5']
[2023-11-11T07:08:25.619+0000] {standard_task_runner.py:85} INFO - Job 3: Subtask split_task
[2023-11-11T07:08:25.783+0000] {task_command.py:416} INFO - Running <TaskInstance: preprocessing_v1.split_task scheduled__2023-11-08T00:00:00+00:00 [running]> on host bce5ad10b059
[2023-11-11T07:08:25.996+0000] {taskinstance.py:1662} INFO - Exporting env vars: AIRFLOW_CTX_DAG_OWNER='Team 3' AIRFLOW_CTX_DAG_ID='preprocessing_v1' AIRFLOW_CTX_TASK_ID='split_task' AIRFLOW_CTX_EXECUTION_DATE='2023-11-08T00:00:00+00:00' AIRFLOW_CTX_TRY_NUMBER='1' AIRFLOW_CTX_DAG_RUN_ID='scheduled__2023-11-08T00:00:00+00:00'
[2023-11-11T07:08:28.057+0000] {python.py:194} INFO - Done. Returned value was: 1
[2023-11-11T07:08:28.105+0000] {taskinstance.py:1400} INFO - Marking task as SUCCESS. dag_id=preprocessing_v1, task_id=split_task, execution_date=20231108T000000, start_date=20231111T070825, end_date=20231111T070828
[2023-11-11T07:08:28.174+0000] {local_task_job_runner.py:228} INFO - Task exited with return code 0
[2023-11-11T07:08:28.289+0000] {taskinstance.py:2778} INFO - 1 downstream tasks scheduled from follow-on schedule check
[2023-11-11T07:14:35.470+0000] {taskinstance.py:1159} INFO - Dependencies all met for dep_context=non-requeueable deps ti=<TaskInstance: preprocessing_v1.split_task scheduled__2023-11-08T00:00:00+00:00 [queued]>
[2023-11-11T07:14:35.486+0000] {taskinstance.py:1159} INFO - Dependencies all met for dep_context=requeueable deps ti=<TaskInstance: preprocessing_v1.split_task scheduled__2023-11-08T00:00:00+00:00 [queued]>
[2023-11-11T07:14:35.486+0000] {taskinstance.py:1361} INFO - Starting attempt 1 of 6
[2023-11-11T07:14:35.502+0000] {taskinstance.py:1382} INFO - Executing <Task(PythonOperator): split_task> on 2023-11-08 00:00:00+00:00
[2023-11-11T07:14:35.524+0000] {standard_task_runner.py:57} INFO - Started process 253 to run task
[2023-11-11T07:14:35.553+0000] {standard_task_runner.py:84} INFO - Running: ['***', 'tasks', 'run', 'preprocessing_v1', 'split_task', 'scheduled__2023-11-08T00:00:00+00:00', '--job-id', '5', '--raw', '--subdir', 'DAGS_FOLDER/***_code.py', '--cfg-path', '/tmp/tmp9en8os5i']
[2023-11-11T07:14:35.566+0000] {standard_task_runner.py:85} INFO - Job 5: Subtask split_task
[2023-11-11T07:14:35.807+0000] {task_command.py:416} INFO - Running <TaskInstance: preprocessing_v1.split_task scheduled__2023-11-08T00:00:00+00:00 [running]> on host ab7bd6d8471a
[2023-11-11T07:14:36.174+0000] {taskinstance.py:1662} INFO - Exporting env vars: AIRFLOW_CTX_DAG_OWNER='Team 3' AIRFLOW_CTX_DAG_ID='preprocessing_v1' AIRFLOW_CTX_TASK_ID='split_task' AIRFLOW_CTX_EXECUTION_DATE='2023-11-08T00:00:00+00:00' AIRFLOW_CTX_TRY_NUMBER='1' AIRFLOW_CTX_DAG_RUN_ID='scheduled__2023-11-08T00:00:00+00:00'
[2023-11-11T07:14:56.830+0000] {job.py:219} ERROR - Job heartbeat got an exception
Traceback (most recent call last):
  File "/home/airflow/.local/lib/python3.8/site-packages/sqlalchemy/engine/base.py", line 3371, in _wrap_pool_connect
    return fn()
  File "/home/airflow/.local/lib/python3.8/site-packages/sqlalchemy/pool/base.py", line 327, in connect
    return _ConnectionFairy._checkout(self)
  File "/home/airflow/.local/lib/python3.8/site-packages/sqlalchemy/pool/base.py", line 894, in _checkout
    fairy = _ConnectionRecord.checkout(pool)
  File "/home/airflow/.local/lib/python3.8/site-packages/sqlalchemy/pool/base.py", line 493, in checkout
    rec = pool._do_get()
  File "/home/airflow/.local/lib/python3.8/site-packages/sqlalchemy/pool/impl.py", line 256, in _do_get
    return self._create_connection()
  File "/home/airflow/.local/lib/python3.8/site-packages/sqlalchemy/pool/base.py", line 273, in _create_connection
    return _ConnectionRecord(self)
  File "/home/airflow/.local/lib/python3.8/site-packages/sqlalchemy/pool/base.py", line 388, in __init__
    self.__connect()
  File "/home/airflow/.local/lib/python3.8/site-packages/sqlalchemy/pool/base.py", line 691, in __connect
    pool.logger.debug("Error on connect(): %s", e)
  File "/home/airflow/.local/lib/python3.8/site-packages/sqlalchemy/util/langhelpers.py", line 70, in __exit__
    compat.raise_(
  File "/home/airflow/.local/lib/python3.8/site-packages/sqlalchemy/util/compat.py", line 211, in raise_
    raise exception
  File "/home/airflow/.local/lib/python3.8/site-packages/sqlalchemy/pool/base.py", line 686, in __connect
    self.dbapi_connection = connection = pool._invoke_creator(self)
  File "/home/airflow/.local/lib/python3.8/site-packages/sqlalchemy/engine/create.py", line 574, in connect
    return dialect.connect(*cargs, **cparams)
  File "/home/airflow/.local/lib/python3.8/site-packages/sqlalchemy/engine/default.py", line 598, in connect
    return self.dbapi.connect(*cargs, **cparams)
  File "/home/airflow/.local/lib/python3.8/site-packages/psycopg2/__init__.py", line 122, in connect
    conn = _connect(dsn, connection_factory=connection_factory, **kwasync)
psycopg2.OperationalError: could not translate host name "postgres" to address: Temporary failure in name resolution


The above exception was the direct cause of the following exception:

Traceback (most recent call last):
  File "/home/airflow/.local/lib/python3.8/site-packages/airflow/jobs/job.py", line 190, in heartbeat
    session.merge(self)
  File "/home/airflow/.local/lib/python3.8/site-packages/sqlalchemy/orm/session.py", line 3056, in merge
    return self._merge(
  File "/home/airflow/.local/lib/python3.8/site-packages/sqlalchemy/orm/session.py", line 3136, in _merge
    merged = self.get(
  File "/home/airflow/.local/lib/python3.8/site-packages/sqlalchemy/orm/session.py", line 2853, in get
    return self._get_impl(
  File "/home/airflow/.local/lib/python3.8/site-packages/sqlalchemy/orm/session.py", line 2975, in _get_impl
    return db_load_fn(
  File "/home/airflow/.local/lib/python3.8/site-packages/sqlalchemy/orm/loading.py", line 530, in load_on_pk_identity
    session.execute(
  File "/home/airflow/.local/lib/python3.8/site-packages/sqlalchemy/orm/session.py", line 1716, in execute
    conn = self._connection_for_bind(bind)
  File "/home/airflow/.local/lib/python3.8/site-packages/sqlalchemy/orm/session.py", line 1555, in _connection_for_bind
    return self._transaction._connection_for_bind(
  File "/home/airflow/.local/lib/python3.8/site-packages/sqlalchemy/orm/session.py", line 750, in _connection_for_bind
    conn = bind.connect()
  File "/home/airflow/.local/lib/python3.8/site-packages/sqlalchemy/future/engine.py", line 406, in connect
    return super(Engine, self).connect()
  File "/home/airflow/.local/lib/python3.8/site-packages/sqlalchemy/engine/base.py", line 3325, in connect
    return self._connection_cls(self, close_with_result=close_with_result)
  File "/home/airflow/.local/lib/python3.8/site-packages/sqlalchemy/engine/base.py", line 96, in __init__
    else engine.raw_connection()
  File "/home/airflow/.local/lib/python3.8/site-packages/sqlalchemy/engine/base.py", line 3404, in raw_connection
    return self._wrap_pool_connect(self.pool.connect, _connection)
  File "/home/airflow/.local/lib/python3.8/site-packages/sqlalchemy/engine/base.py", line 3374, in _wrap_pool_connect
    Connection._handle_dbapi_exception_noconnection(
  File "/home/airflow/.local/lib/python3.8/site-packages/sqlalchemy/engine/base.py", line 2208, in _handle_dbapi_exception_noconnection
    util.raise_(
  File "/home/airflow/.local/lib/python3.8/site-packages/sqlalchemy/util/compat.py", line 211, in raise_
    raise exception
  File "/home/airflow/.local/lib/python3.8/site-packages/sqlalchemy/engine/base.py", line 3371, in _wrap_pool_connect
    return fn()
  File "/home/airflow/.local/lib/python3.8/site-packages/sqlalchemy/pool/base.py", line 327, in connect
    return _ConnectionFairy._checkout(self)
  File "/home/airflow/.local/lib/python3.8/site-packages/sqlalchemy/pool/base.py", line 894, in _checkout
    fairy = _ConnectionRecord.checkout(pool)
  File "/home/airflow/.local/lib/python3.8/site-packages/sqlalchemy/pool/base.py", line 493, in checkout
    rec = pool._do_get()
  File "/home/airflow/.local/lib/python3.8/site-packages/sqlalchemy/pool/impl.py", line 256, in _do_get
    return self._create_connection()
  File "/home/airflow/.local/lib/python3.8/site-packages/sqlalchemy/pool/base.py", line 273, in _create_connection
    return _ConnectionRecord(self)
  File "/home/airflow/.local/lib/python3.8/site-packages/sqlalchemy/pool/base.py", line 388, in __init__
    self.__connect()
  File "/home/airflow/.local/lib/python3.8/site-packages/sqlalchemy/pool/base.py", line 691, in __connect
    pool.logger.debug("Error on connect(): %s", e)
  File "/home/airflow/.local/lib/python3.8/site-packages/sqlalchemy/util/langhelpers.py", line 70, in __exit__
    compat.raise_(
  File "/home/airflow/.local/lib/python3.8/site-packages/sqlalchemy/util/compat.py", line 211, in raise_
    raise exception
  File "/home/airflow/.local/lib/python3.8/site-packages/sqlalchemy/pool/base.py", line 686, in __connect
    self.dbapi_connection = connection = pool._invoke_creator(self)
  File "/home/airflow/.local/lib/python3.8/site-packages/sqlalchemy/engine/create.py", line 574, in connect
    return dialect.connect(*cargs, **cparams)
  File "/home/airflow/.local/lib/python3.8/site-packages/sqlalchemy/engine/default.py", line 598, in connect
    return self.dbapi.connect(*cargs, **cparams)
  File "/home/airflow/.local/lib/python3.8/site-packages/psycopg2/__init__.py", line 122, in connect
    conn = _connect(dsn, connection_factory=connection_factory, **kwasync)
sqlalchemy.exc.OperationalError: (psycopg2.OperationalError) could not translate host name "postgres" to address: Temporary failure in name resolution

(Background on this error at: https://sqlalche.me/e/14/e3q8)
[2023-11-11T07:15:26.554+0000] {job.py:219} ERROR - Job heartbeat got an exception
Traceback (most recent call last):
  File "/home/airflow/.local/lib/python3.8/site-packages/sqlalchemy/engine/base.py", line 3371, in _wrap_pool_connect
    return fn()
  File "/home/airflow/.local/lib/python3.8/site-packages/sqlalchemy/pool/base.py", line 327, in connect
    return _ConnectionFairy._checkout(self)
  File "/home/airflow/.local/lib/python3.8/site-packages/sqlalchemy/pool/base.py", line 894, in _checkout
    fairy = _ConnectionRecord.checkout(pool)
  File "/home/airflow/.local/lib/python3.8/site-packages/sqlalchemy/pool/base.py", line 493, in checkout
    rec = pool._do_get()
  File "/home/airflow/.local/lib/python3.8/site-packages/sqlalchemy/pool/impl.py", line 256, in _do_get
    return self._create_connection()
  File "/home/airflow/.local/lib/python3.8/site-packages/sqlalchemy/pool/base.py", line 273, in _create_connection
    return _ConnectionRecord(self)
  File "/home/airflow/.local/lib/python3.8/site-packages/sqlalchemy/pool/base.py", line 388, in __init__
    self.__connect()
  File "/home/airflow/.local/lib/python3.8/site-packages/sqlalchemy/pool/base.py", line 691, in __connect
    pool.logger.debug("Error on connect(): %s", e)
  File "/home/airflow/.local/lib/python3.8/site-packages/sqlalchemy/util/langhelpers.py", line 70, in __exit__
    compat.raise_(
  File "/home/airflow/.local/lib/python3.8/site-packages/sqlalchemy/util/compat.py", line 211, in raise_
    raise exception
  File "/home/airflow/.local/lib/python3.8/site-packages/sqlalchemy/pool/base.py", line 686, in __connect
    self.dbapi_connection = connection = pool._invoke_creator(self)
  File "/home/airflow/.local/lib/python3.8/site-packages/sqlalchemy/engine/create.py", line 574, in connect
    return dialect.connect(*cargs, **cparams)
  File "/home/airflow/.local/lib/python3.8/site-packages/sqlalchemy/engine/default.py", line 598, in connect
    return self.dbapi.connect(*cargs, **cparams)
  File "/home/airflow/.local/lib/python3.8/site-packages/psycopg2/__init__.py", line 122, in connect
    conn = _connect(dsn, connection_factory=connection_factory, **kwasync)
psycopg2.OperationalError: could not translate host name "postgres" to address: Temporary failure in name resolution


The above exception was the direct cause of the following exception:

Traceback (most recent call last):
  File "/home/airflow/.local/lib/python3.8/site-packages/airflow/jobs/job.py", line 190, in heartbeat
    session.merge(self)
  File "/home/airflow/.local/lib/python3.8/site-packages/sqlalchemy/orm/session.py", line 3056, in merge
    return self._merge(
  File "/home/airflow/.local/lib/python3.8/site-packages/sqlalchemy/orm/session.py", line 3136, in _merge
    merged = self.get(
  File "/home/airflow/.local/lib/python3.8/site-packages/sqlalchemy/orm/session.py", line 2853, in get
    return self._get_impl(
  File "/home/airflow/.local/lib/python3.8/site-packages/sqlalchemy/orm/session.py", line 2975, in _get_impl
    return db_load_fn(
  File "/home/airflow/.local/lib/python3.8/site-packages/sqlalchemy/orm/loading.py", line 530, in load_on_pk_identity
    session.execute(
  File "/home/airflow/.local/lib/python3.8/site-packages/sqlalchemy/orm/session.py", line 1716, in execute
    conn = self._connection_for_bind(bind)
  File "/home/airflow/.local/lib/python3.8/site-packages/sqlalchemy/orm/session.py", line 1555, in _connection_for_bind
    return self._transaction._connection_for_bind(
  File "/home/airflow/.local/lib/python3.8/site-packages/sqlalchemy/orm/session.py", line 750, in _connection_for_bind
    conn = bind.connect()
  File "/home/airflow/.local/lib/python3.8/site-packages/sqlalchemy/future/engine.py", line 406, in connect
    return super(Engine, self).connect()
  File "/home/airflow/.local/lib/python3.8/site-packages/sqlalchemy/engine/base.py", line 3325, in connect
    return self._connection_cls(self, close_with_result=close_with_result)
  File "/home/airflow/.local/lib/python3.8/site-packages/sqlalchemy/engine/base.py", line 96, in __init__
    else engine.raw_connection()
  File "/home/airflow/.local/lib/python3.8/site-packages/sqlalchemy/engine/base.py", line 3404, in raw_connection
    return self._wrap_pool_connect(self.pool.connect, _connection)
  File "/home/airflow/.local/lib/python3.8/site-packages/sqlalchemy/engine/base.py", line 3374, in _wrap_pool_connect
    Connection._handle_dbapi_exception_noconnection(
  File "/home/airflow/.local/lib/python3.8/site-packages/sqlalchemy/engine/base.py", line 2208, in _handle_dbapi_exception_noconnection
    util.raise_(
  File "/home/airflow/.local/lib/python3.8/site-packages/sqlalchemy/util/compat.py", line 211, in raise_
    raise exception
  File "/home/airflow/.local/lib/python3.8/site-packages/sqlalchemy/engine/base.py", line 3371, in _wrap_pool_connect
    return fn()
  File "/home/airflow/.local/lib/python3.8/site-packages/sqlalchemy/pool/base.py", line 327, in connect
    return _ConnectionFairy._checkout(self)
  File "/home/airflow/.local/lib/python3.8/site-packages/sqlalchemy/pool/base.py", line 894, in _checkout
    fairy = _ConnectionRecord.checkout(pool)
  File "/home/airflow/.local/lib/python3.8/site-packages/sqlalchemy/pool/base.py", line 493, in checkout
    rec = pool._do_get()
  File "/home/airflow/.local/lib/python3.8/site-packages/sqlalchemy/pool/impl.py", line 256, in _do_get
    return self._create_connection()
  File "/home/airflow/.local/lib/python3.8/site-packages/sqlalchemy/pool/base.py", line 273, in _create_connection
    return _ConnectionRecord(self)
  File "/home/airflow/.local/lib/python3.8/site-packages/sqlalchemy/pool/base.py", line 388, in __init__
    self.__connect()
  File "/home/airflow/.local/lib/python3.8/site-packages/sqlalchemy/pool/base.py", line 691, in __connect
    pool.logger.debug("Error on connect(): %s", e)
  File "/home/airflow/.local/lib/python3.8/site-packages/sqlalchemy/util/langhelpers.py", line 70, in __exit__
    compat.raise_(
  File "/home/airflow/.local/lib/python3.8/site-packages/sqlalchemy/util/compat.py", line 211, in raise_
    raise exception
  File "/home/airflow/.local/lib/python3.8/site-packages/sqlalchemy/pool/base.py", line 686, in __connect
    self.dbapi_connection = connection = pool._invoke_creator(self)
  File "/home/airflow/.local/lib/python3.8/site-packages/sqlalchemy/engine/create.py", line 574, in connect
    return dialect.connect(*cargs, **cparams)
  File "/home/airflow/.local/lib/python3.8/site-packages/sqlalchemy/engine/default.py", line 598, in connect
    return self.dbapi.connect(*cargs, **cparams)
  File "/home/airflow/.local/lib/python3.8/site-packages/psycopg2/__init__.py", line 122, in connect
    conn = _connect(dsn, connection_factory=connection_factory, **kwasync)
sqlalchemy.exc.OperationalError: (psycopg2.OperationalError) could not translate host name "postgres" to address: Temporary failure in name resolution

(Background on this error at: https://sqlalche.me/e/14/e3q8)
[2023-11-11T07:15:43.358+0000] {job.py:219} ERROR - Job heartbeat got an exception
Traceback (most recent call last):
  File "/home/airflow/.local/lib/python3.8/site-packages/sqlalchemy/engine/base.py", line 3371, in _wrap_pool_connect
    return fn()
  File "/home/airflow/.local/lib/python3.8/site-packages/sqlalchemy/pool/base.py", line 327, in connect
    return _ConnectionFairy._checkout(self)
  File "/home/airflow/.local/lib/python3.8/site-packages/sqlalchemy/pool/base.py", line 894, in _checkout
    fairy = _ConnectionRecord.checkout(pool)
  File "/home/airflow/.local/lib/python3.8/site-packages/sqlalchemy/pool/base.py", line 493, in checkout
    rec = pool._do_get()
  File "/home/airflow/.local/lib/python3.8/site-packages/sqlalchemy/pool/impl.py", line 256, in _do_get
    return self._create_connection()
  File "/home/airflow/.local/lib/python3.8/site-packages/sqlalchemy/pool/base.py", line 273, in _create_connection
    return _ConnectionRecord(self)
  File "/home/airflow/.local/lib/python3.8/site-packages/sqlalchemy/pool/base.py", line 388, in __init__
    self.__connect()
  File "/home/airflow/.local/lib/python3.8/site-packages/sqlalchemy/pool/base.py", line 691, in __connect
    pool.logger.debug("Error on connect(): %s", e)
  File "/home/airflow/.local/lib/python3.8/site-packages/sqlalchemy/util/langhelpers.py", line 70, in __exit__
    compat.raise_(
  File "/home/airflow/.local/lib/python3.8/site-packages/sqlalchemy/util/compat.py", line 211, in raise_
    raise exception
  File "/home/airflow/.local/lib/python3.8/site-packages/sqlalchemy/pool/base.py", line 686, in __connect
    self.dbapi_connection = connection = pool._invoke_creator(self)
  File "/home/airflow/.local/lib/python3.8/site-packages/sqlalchemy/engine/create.py", line 574, in connect
    return dialect.connect(*cargs, **cparams)
  File "/home/airflow/.local/lib/python3.8/site-packages/sqlalchemy/engine/default.py", line 598, in connect
    return self.dbapi.connect(*cargs, **cparams)
  File "/home/airflow/.local/lib/python3.8/site-packages/psycopg2/__init__.py", line 122, in connect
    conn = _connect(dsn, connection_factory=connection_factory, **kwasync)
psycopg2.OperationalError: could not translate host name "postgres" to address: Temporary failure in name resolution


The above exception was the direct cause of the following exception:

Traceback (most recent call last):
  File "/home/airflow/.local/lib/python3.8/site-packages/airflow/jobs/job.py", line 190, in heartbeat
    session.merge(self)
  File "/home/airflow/.local/lib/python3.8/site-packages/sqlalchemy/orm/session.py", line 3056, in merge
    return self._merge(
  File "/home/airflow/.local/lib/python3.8/site-packages/sqlalchemy/orm/session.py", line 3136, in _merge
    merged = self.get(
  File "/home/airflow/.local/lib/python3.8/site-packages/sqlalchemy/orm/session.py", line 2853, in get
    return self._get_impl(
  File "/home/airflow/.local/lib/python3.8/site-packages/sqlalchemy/orm/session.py", line 2975, in _get_impl
    return db_load_fn(
  File "/home/airflow/.local/lib/python3.8/site-packages/sqlalchemy/orm/loading.py", line 530, in load_on_pk_identity
    session.execute(
  File "/home/airflow/.local/lib/python3.8/site-packages/sqlalchemy/orm/session.py", line 1716, in execute
    conn = self._connection_for_bind(bind)
  File "/home/airflow/.local/lib/python3.8/site-packages/sqlalchemy/orm/session.py", line 1555, in _connection_for_bind
    return self._transaction._connection_for_bind(
  File "/home/airflow/.local/lib/python3.8/site-packages/sqlalchemy/orm/session.py", line 750, in _connection_for_bind
    conn = bind.connect()
  File "/home/airflow/.local/lib/python3.8/site-packages/sqlalchemy/future/engine.py", line 406, in connect
    return super(Engine, self).connect()
  File "/home/airflow/.local/lib/python3.8/site-packages/sqlalchemy/engine/base.py", line 3325, in connect
    return self._connection_cls(self, close_with_result=close_with_result)
  File "/home/airflow/.local/lib/python3.8/site-packages/sqlalchemy/engine/base.py", line 96, in __init__
    else engine.raw_connection()
  File "/home/airflow/.local/lib/python3.8/site-packages/sqlalchemy/engine/base.py", line 3404, in raw_connection
    return self._wrap_pool_connect(self.pool.connect, _connection)
  File "/home/airflow/.local/lib/python3.8/site-packages/sqlalchemy/engine/base.py", line 3374, in _wrap_pool_connect
    Connection._handle_dbapi_exception_noconnection(
  File "/home/airflow/.local/lib/python3.8/site-packages/sqlalchemy/engine/base.py", line 2208, in _handle_dbapi_exception_noconnection
    util.raise_(
  File "/home/airflow/.local/lib/python3.8/site-packages/sqlalchemy/util/compat.py", line 211, in raise_
    raise exception
  File "/home/airflow/.local/lib/python3.8/site-packages/sqlalchemy/engine/base.py", line 3371, in _wrap_pool_connect
    return fn()
  File "/home/airflow/.local/lib/python3.8/site-packages/sqlalchemy/pool/base.py", line 327, in connect
    return _ConnectionFairy._checkout(self)
  File "/home/airflow/.local/lib/python3.8/site-packages/sqlalchemy/pool/base.py", line 894, in _checkout
    fairy = _ConnectionRecord.checkout(pool)
  File "/home/airflow/.local/lib/python3.8/site-packages/sqlalchemy/pool/base.py", line 493, in checkout
    rec = pool._do_get()
  File "/home/airflow/.local/lib/python3.8/site-packages/sqlalchemy/pool/impl.py", line 256, in _do_get
    return self._create_connection()
  File "/home/airflow/.local/lib/python3.8/site-packages/sqlalchemy/pool/base.py", line 273, in _create_connection
    return _ConnectionRecord(self)
  File "/home/airflow/.local/lib/python3.8/site-packages/sqlalchemy/pool/base.py", line 388, in __init__
    self.__connect()
  File "/home/airflow/.local/lib/python3.8/site-packages/sqlalchemy/pool/base.py", line 691, in __connect
    pool.logger.debug("Error on connect(): %s", e)
  File "/home/airflow/.local/lib/python3.8/site-packages/sqlalchemy/util/langhelpers.py", line 70, in __exit__
    compat.raise_(
  File "/home/airflow/.local/lib/python3.8/site-packages/sqlalchemy/util/compat.py", line 211, in raise_
    raise exception
  File "/home/airflow/.local/lib/python3.8/site-packages/sqlalchemy/pool/base.py", line 686, in __connect
    self.dbapi_connection = connection = pool._invoke_creator(self)
  File "/home/airflow/.local/lib/python3.8/site-packages/sqlalchemy/engine/create.py", line 574, in connect
    return dialect.connect(*cargs, **cparams)
  File "/home/airflow/.local/lib/python3.8/site-packages/sqlalchemy/engine/default.py", line 598, in connect
    return self.dbapi.connect(*cargs, **cparams)
  File "/home/airflow/.local/lib/python3.8/site-packages/psycopg2/__init__.py", line 122, in connect
    conn = _connect(dsn, connection_factory=connection_factory, **kwasync)
sqlalchemy.exc.OperationalError: (psycopg2.OperationalError) could not translate host name "postgres" to address: Temporary failure in name resolution

(Background on this error at: https://sqlalche.me/e/14/e3q8)
[2023-11-11T07:16:04.909+0000] {local_task_job_runner.py:115} ERROR - Received SIGTERM. Terminating subprocesses
[2023-11-11T07:16:05.263+0000] {process_utils.py:131} INFO - Sending 15 to group 253. PIDs of all processes in the group: [253]
[2023-11-11T07:16:05.271+0000] {process_utils.py:86} INFO - Sending the signal 15 to group 253
[2023-11-11T07:16:05.345+0000] {taskinstance.py:1632} ERROR - Received SIGTERM. Terminating subprocesses.
[2023-11-11T07:16:07.280+0000] {taskinstance.py:1937} ERROR - Task failed with exception
Traceback (most recent call last):
  File "/home/airflow/.local/lib/python3.8/site-packages/airflow/operators/python.py", line 192, in execute
    return_value = self.execute_callable()
  File "/home/airflow/.local/lib/python3.8/site-packages/airflow/operators/python.py", line 209, in execute_callable
    return self.python_callable(*self.op_args, **self.op_kwargs)
  File "/opt/airflow/dags/src/datapreprocessing.py", line 30, in split_dataset
    X_test.to_csv(os.path.join(os.path.dirname(__file__), "../data/X_test.csv"), index=False)
  File "/home/airflow/.local/lib/python3.8/site-packages/pandas/core/generic.py", line 3772, in to_csv
    return DataFrameRenderer(formatter).to_csv(
  File "/home/airflow/.local/lib/python3.8/site-packages/pandas/io/formats/format.py", line 1186, in to_csv
    csv_formatter.save()
  File "/home/airflow/.local/lib/python3.8/site-packages/pandas/io/formats/csvs.py", line 259, in save
    self._save()
  File "/home/airflow/.local/lib/python3.8/site-packages/pandas/io/formats/csvs.py", line 264, in _save
    self._save_body()
  File "/home/airflow/.local/lib/python3.8/site-packages/pandas/io/formats/csvs.py", line 302, in _save_body
    self._save_chunk(start_i, end_i)
  File "/home/airflow/.local/lib/python3.8/site-packages/pandas/io/formats/csvs.py", line 313, in _save_chunk
    libwriters.write_csv_rows(
  File "pandas/_libs/writers.pyx", line 72, in pandas._libs.writers.write_csv_rows
  File "/home/airflow/.local/lib/python3.8/site-packages/airflow/models/taskinstance.py", line 1634, in signal_handler
    raise AirflowException("Task received SIGTERM signal")
airflow.exceptions.AirflowException: Task received SIGTERM signal
[2023-11-11T07:16:08.240+0000] {taskinstance.py:1400} INFO - Marking task as UP_FOR_RETRY. dag_id=preprocessing_v1, task_id=split_task, execution_date=20231108T000000, start_date=20231111T071435, end_date=20231111T071608
[2023-11-11T07:16:08.560+0000] {standard_task_runner.py:104} ERROR - Failed to execute job 5 for task split_task (Task received SIGTERM signal; 253)
[2023-11-11T07:16:08.720+0000] {process_utils.py:79} INFO - Process psutil.Process(pid=253, status='terminated', exitcode=1, started='07:14:34') (253) terminated with exit code 1
[2023-11-11T07:16:08.843+0000] {local_task_job_runner.py:228} INFO - Task exited with return code 143
[2023-11-11T07:16:10.613+0000] {taskinstance.py:2778} INFO - 0 downstream tasks scheduled from follow-on schedule check
[2023-11-11T07:17:53.004+0000] {taskinstance.py:1159} INFO - Dependencies all met for dep_context=non-requeueable deps ti=<TaskInstance: preprocessing_v1.split_task scheduled__2023-11-08T00:00:00+00:00 [queued]>
[2023-11-11T07:17:53.013+0000] {taskinstance.py:1159} INFO - Dependencies all met for dep_context=requeueable deps ti=<TaskInstance: preprocessing_v1.split_task scheduled__2023-11-08T00:00:00+00:00 [queued]>
[2023-11-11T07:17:53.013+0000] {taskinstance.py:1361} INFO - Starting attempt 1 of 6
[2023-11-11T07:17:53.022+0000] {taskinstance.py:1382} INFO - Executing <Task(PythonOperator): split_task> on 2023-11-08 00:00:00+00:00
[2023-11-11T07:17:53.043+0000] {standard_task_runner.py:57} INFO - Started process 251 to run task
[2023-11-11T07:17:53.049+0000] {standard_task_runner.py:84} INFO - Running: ['***', 'tasks', 'run', 'preprocessing_v1', 'split_task', 'scheduled__2023-11-08T00:00:00+00:00', '--job-id', '3', '--raw', '--subdir', 'DAGS_FOLDER/***_code.py', '--cfg-path', '/tmp/tmpdc75w9v7']
[2023-11-11T07:17:53.052+0000] {standard_task_runner.py:85} INFO - Job 3: Subtask split_task
[2023-11-11T07:17:53.119+0000] {task_command.py:416} INFO - Running <TaskInstance: preprocessing_v1.split_task scheduled__2023-11-08T00:00:00+00:00 [running]> on host 2c83865699e0
[2023-11-11T07:17:53.203+0000] {taskinstance.py:1662} INFO - Exporting env vars: AIRFLOW_CTX_DAG_OWNER='Team 3' AIRFLOW_CTX_DAG_ID='preprocessing_v1' AIRFLOW_CTX_TASK_ID='split_task' AIRFLOW_CTX_EXECUTION_DATE='2023-11-08T00:00:00+00:00' AIRFLOW_CTX_TRY_NUMBER='1' AIRFLOW_CTX_DAG_RUN_ID='scheduled__2023-11-08T00:00:00+00:00'
[2023-11-11T07:17:55.757+0000] {python.py:194} INFO - Done. Returned value was: 1
[2023-11-11T07:17:55.862+0000] {taskinstance.py:1400} INFO - Marking task as SUCCESS. dag_id=preprocessing_v1, task_id=split_task, execution_date=20231108T000000, start_date=20231111T071753, end_date=20231111T071755
[2023-11-11T07:17:55.937+0000] {local_task_job_runner.py:228} INFO - Task exited with return code 0
[2023-11-11T07:17:56.006+0000] {taskinstance.py:2778} INFO - 1 downstream tasks scheduled from follow-on schedule check
