[2023-11-11T03:25:19.613+0000] {taskinstance.py:1159} INFO - Dependencies all met for dep_context=non-requeueable deps ti=<TaskInstance: preprocessing_v1.split_task scheduled__2023-11-09T00:00:00+00:00 [queued]>
[2023-11-11T03:25:19.619+0000] {taskinstance.py:1159} INFO - Dependencies all met for dep_context=requeueable deps ti=<TaskInstance: preprocessing_v1.split_task scheduled__2023-11-09T00:00:00+00:00 [queued]>
[2023-11-11T03:25:19.620+0000] {taskinstance.py:1361} INFO - Starting attempt 1 of 6
[2023-11-11T03:25:19.629+0000] {taskinstance.py:1382} INFO - Executing <Task(PythonOperator): split_task> on 2023-11-09 00:00:00+00:00
[2023-11-11T03:25:19.635+0000] {standard_task_runner.py:57} INFO - Started process 238 to run task
[2023-11-11T03:25:19.644+0000] {standard_task_runner.py:84} INFO - Running: ['***', 'tasks', 'run', 'preprocessing_v1', 'split_task', 'scheduled__2023-11-09T00:00:00+00:00', '--job-id', '7', '--raw', '--subdir', 'DAGS_FOLDER/***_code.py', '--cfg-path', '/tmp/tmplgcjuqmj']
[2023-11-11T03:25:19.647+0000] {standard_task_runner.py:85} INFO - Job 7: Subtask split_task
[2023-11-11T03:25:19.691+0000] {task_command.py:416} INFO - Running <TaskInstance: preprocessing_v1.split_task scheduled__2023-11-09T00:00:00+00:00 [running]> on host d2c761eebca3
[2023-11-11T03:25:19.750+0000] {taskinstance.py:1662} INFO - Exporting env vars: AIRFLOW_CTX_DAG_OWNER='Team 3' AIRFLOW_CTX_DAG_ID='preprocessing_v1' AIRFLOW_CTX_TASK_ID='split_task' AIRFLOW_CTX_EXECUTION_DATE='2023-11-09T00:00:00+00:00' AIRFLOW_CTX_TRY_NUMBER='1' AIRFLOW_CTX_DAG_RUN_ID='scheduled__2023-11-09T00:00:00+00:00'
[2023-11-11T03:25:21.210+0000] {python.py:194} INFO - Done. Returned value was: 1
[2023-11-11T03:25:21.226+0000] {taskinstance.py:1400} INFO - Marking task as SUCCESS. dag_id=preprocessing_v1, task_id=split_task, execution_date=20231109T000000, start_date=20231111T032519, end_date=20231111T032521
[2023-11-11T03:25:21.248+0000] {local_task_job_runner.py:228} INFO - Task exited with return code 0
[2023-11-11T03:25:21.266+0000] {taskinstance.py:2778} INFO - 1 downstream tasks scheduled from follow-on schedule check
[2023-11-11T03:29:36.788+0000] {taskinstance.py:1159} INFO - Dependencies all met for dep_context=non-requeueable deps ti=<TaskInstance: preprocessing_v1.split_task scheduled__2023-11-09T00:00:00+00:00 [queued]>
[2023-11-11T03:29:36.795+0000] {taskinstance.py:1159} INFO - Dependencies all met for dep_context=requeueable deps ti=<TaskInstance: preprocessing_v1.split_task scheduled__2023-11-09T00:00:00+00:00 [queued]>
[2023-11-11T03:29:36.795+0000] {taskinstance.py:1361} INFO - Starting attempt 1 of 6
[2023-11-11T03:29:36.803+0000] {taskinstance.py:1382} INFO - Executing <Task(PythonOperator): split_task> on 2023-11-09 00:00:00+00:00
[2023-11-11T03:29:36.809+0000] {standard_task_runner.py:57} INFO - Started process 251 to run task
[2023-11-11T03:29:36.813+0000] {standard_task_runner.py:84} INFO - Running: ['***', 'tasks', 'run', 'preprocessing_v1', 'split_task', 'scheduled__2023-11-09T00:00:00+00:00', '--job-id', '3', '--raw', '--subdir', 'DAGS_FOLDER/***_code.py', '--cfg-path', '/tmp/tmp6qgizst9']
[2023-11-11T03:29:36.817+0000] {standard_task_runner.py:85} INFO - Job 3: Subtask split_task
[2023-11-11T03:29:36.883+0000] {task_command.py:416} INFO - Running <TaskInstance: preprocessing_v1.split_task scheduled__2023-11-09T00:00:00+00:00 [running]> on host 9c8a8ec1a519
[2023-11-11T03:29:36.953+0000] {taskinstance.py:1662} INFO - Exporting env vars: AIRFLOW_CTX_DAG_OWNER='Team 3' AIRFLOW_CTX_DAG_ID='preprocessing_v1' AIRFLOW_CTX_TASK_ID='split_task' AIRFLOW_CTX_EXECUTION_DATE='2023-11-09T00:00:00+00:00' AIRFLOW_CTX_TRY_NUMBER='1' AIRFLOW_CTX_DAG_RUN_ID='scheduled__2023-11-09T00:00:00+00:00'
[2023-11-11T03:29:38.390+0000] {python.py:194} INFO - Done. Returned value was: 1
[2023-11-11T03:29:38.406+0000] {taskinstance.py:1400} INFO - Marking task as SUCCESS. dag_id=preprocessing_v1, task_id=split_task, execution_date=20231109T000000, start_date=20231111T032936, end_date=20231111T032938
[2023-11-11T03:29:38.453+0000] {local_task_job_runner.py:228} INFO - Task exited with return code 0
[2023-11-11T03:29:38.469+0000] {taskinstance.py:2778} INFO - 1 downstream tasks scheduled from follow-on schedule check
[2023-11-11T03:41:55.286+0000] {taskinstance.py:1159} INFO - Dependencies all met for dep_context=non-requeueable deps ti=<TaskInstance: preprocessing_v1.split_task scheduled__2023-11-09T00:00:00+00:00 [queued]>
[2023-11-11T03:41:55.292+0000] {taskinstance.py:1159} INFO - Dependencies all met for dep_context=requeueable deps ti=<TaskInstance: preprocessing_v1.split_task scheduled__2023-11-09T00:00:00+00:00 [queued]>
[2023-11-11T03:41:55.292+0000] {taskinstance.py:1361} INFO - Starting attempt 1 of 6
[2023-11-11T03:41:55.300+0000] {taskinstance.py:1382} INFO - Executing <Task(PythonOperator): split_task> on 2023-11-09 00:00:00+00:00
[2023-11-11T03:41:55.309+0000] {standard_task_runner.py:57} INFO - Started process 229 to run task
[2023-11-11T03:41:55.326+0000] {standard_task_runner.py:84} INFO - Running: ['***', 'tasks', 'run', 'preprocessing_v1', 'split_task', 'scheduled__2023-11-09T00:00:00+00:00', '--job-id', '3', '--raw', '--subdir', 'DAGS_FOLDER/***_code.py', '--cfg-path', '/tmp/tmpsmhpjbgg']
[2023-11-11T03:41:55.330+0000] {standard_task_runner.py:85} INFO - Job 3: Subtask split_task
[2023-11-11T03:41:55.404+0000] {task_command.py:416} INFO - Running <TaskInstance: preprocessing_v1.split_task scheduled__2023-11-09T00:00:00+00:00 [running]> on host 27df91229c7e
[2023-11-11T03:41:55.459+0000] {taskinstance.py:1662} INFO - Exporting env vars: AIRFLOW_CTX_DAG_OWNER='Team 3' AIRFLOW_CTX_DAG_ID='preprocessing_v1' AIRFLOW_CTX_TASK_ID='split_task' AIRFLOW_CTX_EXECUTION_DATE='2023-11-09T00:00:00+00:00' AIRFLOW_CTX_TRY_NUMBER='1' AIRFLOW_CTX_DAG_RUN_ID='scheduled__2023-11-09T00:00:00+00:00'
[2023-11-11T03:41:55.460+0000] {datapreprocessing.py:40} INFO - Splitting dataset...
[2023-11-11T03:41:57.312+0000] {datapreprocessing.py:52} INFO - Dataset split.
[2023-11-11T03:41:57.315+0000] {python.py:194} INFO - Done. Returned value was: 1
[2023-11-11T03:41:57.331+0000] {taskinstance.py:1400} INFO - Marking task as SUCCESS. dag_id=preprocessing_v1, task_id=split_task, execution_date=20231109T000000, start_date=20231111T034155, end_date=20231111T034157
[2023-11-11T03:41:57.352+0000] {local_task_job_runner.py:228} INFO - Task exited with return code 0
[2023-11-11T03:41:57.370+0000] {taskinstance.py:2778} INFO - 1 downstream tasks scheduled from follow-on schedule check
[2023-11-11T04:44:18.637+0000] {taskinstance.py:1159} INFO - Dependencies all met for dep_context=non-requeueable deps ti=<TaskInstance: preprocessing_v1.split_task scheduled__2023-11-09T00:00:00+00:00 [queued]>
[2023-11-11T04:44:18.643+0000] {taskinstance.py:1159} INFO - Dependencies all met for dep_context=requeueable deps ti=<TaskInstance: preprocessing_v1.split_task scheduled__2023-11-09T00:00:00+00:00 [queued]>
[2023-11-11T04:44:18.643+0000] {taskinstance.py:1361} INFO - Starting attempt 1 of 6
[2023-11-11T04:44:18.651+0000] {taskinstance.py:1382} INFO - Executing <Task(PythonOperator): split_task> on 2023-11-09 00:00:00+00:00
[2023-11-11T04:44:18.659+0000] {standard_task_runner.py:57} INFO - Started process 229 to run task
[2023-11-11T04:44:18.664+0000] {standard_task_runner.py:84} INFO - Running: ['***', 'tasks', 'run', 'preprocessing_v1', 'split_task', 'scheduled__2023-11-09T00:00:00+00:00', '--job-id', '4', '--raw', '--subdir', 'DAGS_FOLDER/***_code.py', '--cfg-path', '/tmp/tmpsoja26t9']
[2023-11-11T04:44:18.668+0000] {standard_task_runner.py:85} INFO - Job 4: Subtask split_task
[2023-11-11T04:44:18.725+0000] {task_command.py:416} INFO - Running <TaskInstance: preprocessing_v1.split_task scheduled__2023-11-09T00:00:00+00:00 [running]> on host bb20688940fc
[2023-11-11T04:44:18.784+0000] {taskinstance.py:1662} INFO - Exporting env vars: AIRFLOW_CTX_DAG_OWNER='Team 3' AIRFLOW_CTX_DAG_ID='preprocessing_v1' AIRFLOW_CTX_TASK_ID='split_task' AIRFLOW_CTX_EXECUTION_DATE='2023-11-09T00:00:00+00:00' AIRFLOW_CTX_TRY_NUMBER='1' AIRFLOW_CTX_DAG_RUN_ID='scheduled__2023-11-09T00:00:00+00:00'
[2023-11-11T04:44:18.786+0000] {datapreprocessing.py:39} INFO - Splitting dataset...
[2023-11-11T04:44:21.019+0000] {datapreprocessing.py:51} INFO - Dataset split.
[2023-11-11T04:44:21.022+0000] {python.py:194} INFO - Done. Returned value was: 1
[2023-11-11T04:44:21.042+0000] {taskinstance.py:1400} INFO - Marking task as SUCCESS. dag_id=preprocessing_v1, task_id=split_task, execution_date=20231109T000000, start_date=20231111T044418, end_date=20231111T044421
[2023-11-11T04:44:21.070+0000] {local_task_job_runner.py:228} INFO - Task exited with return code 0
[2023-11-11T04:44:21.106+0000] {taskinstance.py:2778} INFO - 1 downstream tasks scheduled from follow-on schedule check
[2023-11-11T07:08:25.497+0000] {taskinstance.py:1159} INFO - Dependencies all met for dep_context=non-requeueable deps ti=<TaskInstance: preprocessing_v1.split_task scheduled__2023-11-09T00:00:00+00:00 [queued]>
[2023-11-11T07:08:25.510+0000] {taskinstance.py:1159} INFO - Dependencies all met for dep_context=requeueable deps ti=<TaskInstance: preprocessing_v1.split_task scheduled__2023-11-09T00:00:00+00:00 [queued]>
[2023-11-11T07:08:25.511+0000] {taskinstance.py:1361} INFO - Starting attempt 1 of 6
[2023-11-11T07:08:25.524+0000] {taskinstance.py:1382} INFO - Executing <Task(PythonOperator): split_task> on 2023-11-09 00:00:00+00:00
[2023-11-11T07:08:25.571+0000] {standard_task_runner.py:57} INFO - Started process 254 to run task
[2023-11-11T07:08:25.605+0000] {standard_task_runner.py:84} INFO - Running: ['***', 'tasks', 'run', 'preprocessing_v1', 'split_task', 'scheduled__2023-11-09T00:00:00+00:00', '--job-id', '4', '--raw', '--subdir', 'DAGS_FOLDER/***_code.py', '--cfg-path', '/tmp/tmpdxnymy56']
[2023-11-11T07:08:25.619+0000] {standard_task_runner.py:85} INFO - Job 4: Subtask split_task
[2023-11-11T07:08:25.790+0000] {task_command.py:416} INFO - Running <TaskInstance: preprocessing_v1.split_task scheduled__2023-11-09T00:00:00+00:00 [running]> on host bce5ad10b059
[2023-11-11T07:08:25.996+0000] {taskinstance.py:1662} INFO - Exporting env vars: AIRFLOW_CTX_DAG_OWNER='Team 3' AIRFLOW_CTX_DAG_ID='preprocessing_v1' AIRFLOW_CTX_TASK_ID='split_task' AIRFLOW_CTX_EXECUTION_DATE='2023-11-09T00:00:00+00:00' AIRFLOW_CTX_TRY_NUMBER='1' AIRFLOW_CTX_DAG_RUN_ID='scheduled__2023-11-09T00:00:00+00:00'
[2023-11-11T07:08:28.769+0000] {python.py:194} INFO - Done. Returned value was: 1
[2023-11-11T07:08:28.976+0000] {taskinstance.py:1400} INFO - Marking task as SUCCESS. dag_id=preprocessing_v1, task_id=split_task, execution_date=20231109T000000, start_date=20231111T070825, end_date=20231111T070828
[2023-11-11T07:08:29.108+0000] {local_task_job_runner.py:228} INFO - Task exited with return code 0
[2023-11-11T07:08:29.340+0000] {taskinstance.py:2778} INFO - 1 downstream tasks scheduled from follow-on schedule check
[2023-11-11T07:14:35.474+0000] {taskinstance.py:1159} INFO - Dependencies all met for dep_context=non-requeueable deps ti=<TaskInstance: preprocessing_v1.split_task scheduled__2023-11-09T00:00:00+00:00 [queued]>
[2023-11-11T07:14:35.487+0000] {taskinstance.py:1159} INFO - Dependencies all met for dep_context=requeueable deps ti=<TaskInstance: preprocessing_v1.split_task scheduled__2023-11-09T00:00:00+00:00 [queued]>
[2023-11-11T07:14:35.488+0000] {taskinstance.py:1361} INFO - Starting attempt 1 of 6
[2023-11-11T07:14:35.503+0000] {taskinstance.py:1382} INFO - Executing <Task(PythonOperator): split_task> on 2023-11-09 00:00:00+00:00
[2023-11-11T07:14:35.521+0000] {standard_task_runner.py:57} INFO - Started process 252 to run task
[2023-11-11T07:14:35.537+0000] {standard_task_runner.py:84} INFO - Running: ['***', 'tasks', 'run', 'preprocessing_v1', 'split_task', 'scheduled__2023-11-09T00:00:00+00:00', '--job-id', '6', '--raw', '--subdir', 'DAGS_FOLDER/***_code.py', '--cfg-path', '/tmp/tmpx14l71e5']
[2023-11-11T07:14:35.558+0000] {standard_task_runner.py:85} INFO - Job 6: Subtask split_task
[2023-11-11T07:14:35.791+0000] {task_command.py:416} INFO - Running <TaskInstance: preprocessing_v1.split_task scheduled__2023-11-09T00:00:00+00:00 [running]> on host ab7bd6d8471a
[2023-11-11T07:14:36.120+0000] {taskinstance.py:1662} INFO - Exporting env vars: AIRFLOW_CTX_DAG_OWNER='Team 3' AIRFLOW_CTX_DAG_ID='preprocessing_v1' AIRFLOW_CTX_TASK_ID='split_task' AIRFLOW_CTX_EXECUTION_DATE='2023-11-09T00:00:00+00:00' AIRFLOW_CTX_TRY_NUMBER='1' AIRFLOW_CTX_DAG_RUN_ID='scheduled__2023-11-09T00:00:00+00:00'
[2023-11-11T07:14:56.682+0000] {job.py:219} ERROR - Job heartbeat got an exception
Traceback (most recent call last):
  File "/home/airflow/.local/lib/python3.8/site-packages/sqlalchemy/engine/base.py", line 3371, in _wrap_pool_connect
    return fn()
  File "/home/airflow/.local/lib/python3.8/site-packages/sqlalchemy/pool/base.py", line 327, in connect
    return _ConnectionFairy._checkout(self)
  File "/home/airflow/.local/lib/python3.8/site-packages/sqlalchemy/pool/base.py", line 894, in _checkout
    fairy = _ConnectionRecord.checkout(pool)
  File "/home/airflow/.local/lib/python3.8/site-packages/sqlalchemy/pool/base.py", line 493, in checkout
    rec = pool._do_get()
  File "/home/airflow/.local/lib/python3.8/site-packages/sqlalchemy/pool/impl.py", line 256, in _do_get
    return self._create_connection()
  File "/home/airflow/.local/lib/python3.8/site-packages/sqlalchemy/pool/base.py", line 273, in _create_connection
    return _ConnectionRecord(self)
  File "/home/airflow/.local/lib/python3.8/site-packages/sqlalchemy/pool/base.py", line 388, in __init__
    self.__connect()
  File "/home/airflow/.local/lib/python3.8/site-packages/sqlalchemy/pool/base.py", line 691, in __connect
    pool.logger.debug("Error on connect(): %s", e)
  File "/home/airflow/.local/lib/python3.8/site-packages/sqlalchemy/util/langhelpers.py", line 70, in __exit__
    compat.raise_(
  File "/home/airflow/.local/lib/python3.8/site-packages/sqlalchemy/util/compat.py", line 211, in raise_
    raise exception
  File "/home/airflow/.local/lib/python3.8/site-packages/sqlalchemy/pool/base.py", line 686, in __connect
    self.dbapi_connection = connection = pool._invoke_creator(self)
  File "/home/airflow/.local/lib/python3.8/site-packages/sqlalchemy/engine/create.py", line 574, in connect
    return dialect.connect(*cargs, **cparams)
  File "/home/airflow/.local/lib/python3.8/site-packages/sqlalchemy/engine/default.py", line 598, in connect
    return self.dbapi.connect(*cargs, **cparams)
  File "/home/airflow/.local/lib/python3.8/site-packages/psycopg2/__init__.py", line 122, in connect
    conn = _connect(dsn, connection_factory=connection_factory, **kwasync)
psycopg2.OperationalError: could not translate host name "postgres" to address: Temporary failure in name resolution


The above exception was the direct cause of the following exception:

Traceback (most recent call last):
  File "/home/airflow/.local/lib/python3.8/site-packages/airflow/jobs/job.py", line 190, in heartbeat
    session.merge(self)
  File "/home/airflow/.local/lib/python3.8/site-packages/sqlalchemy/orm/session.py", line 3056, in merge
    return self._merge(
  File "/home/airflow/.local/lib/python3.8/site-packages/sqlalchemy/orm/session.py", line 3136, in _merge
    merged = self.get(
  File "/home/airflow/.local/lib/python3.8/site-packages/sqlalchemy/orm/session.py", line 2853, in get
    return self._get_impl(
  File "/home/airflow/.local/lib/python3.8/site-packages/sqlalchemy/orm/session.py", line 2975, in _get_impl
    return db_load_fn(
  File "/home/airflow/.local/lib/python3.8/site-packages/sqlalchemy/orm/loading.py", line 530, in load_on_pk_identity
    session.execute(
  File "/home/airflow/.local/lib/python3.8/site-packages/sqlalchemy/orm/session.py", line 1716, in execute
    conn = self._connection_for_bind(bind)
  File "/home/airflow/.local/lib/python3.8/site-packages/sqlalchemy/orm/session.py", line 1555, in _connection_for_bind
    return self._transaction._connection_for_bind(
  File "/home/airflow/.local/lib/python3.8/site-packages/sqlalchemy/orm/session.py", line 750, in _connection_for_bind
    conn = bind.connect()
  File "/home/airflow/.local/lib/python3.8/site-packages/sqlalchemy/future/engine.py", line 406, in connect
    return super(Engine, self).connect()
  File "/home/airflow/.local/lib/python3.8/site-packages/sqlalchemy/engine/base.py", line 3325, in connect
    return self._connection_cls(self, close_with_result=close_with_result)
  File "/home/airflow/.local/lib/python3.8/site-packages/sqlalchemy/engine/base.py", line 96, in __init__
    else engine.raw_connection()
  File "/home/airflow/.local/lib/python3.8/site-packages/sqlalchemy/engine/base.py", line 3404, in raw_connection
    return self._wrap_pool_connect(self.pool.connect, _connection)
  File "/home/airflow/.local/lib/python3.8/site-packages/sqlalchemy/engine/base.py", line 3374, in _wrap_pool_connect
    Connection._handle_dbapi_exception_noconnection(
  File "/home/airflow/.local/lib/python3.8/site-packages/sqlalchemy/engine/base.py", line 2208, in _handle_dbapi_exception_noconnection
    util.raise_(
  File "/home/airflow/.local/lib/python3.8/site-packages/sqlalchemy/util/compat.py", line 211, in raise_
    raise exception
  File "/home/airflow/.local/lib/python3.8/site-packages/sqlalchemy/engine/base.py", line 3371, in _wrap_pool_connect
    return fn()
  File "/home/airflow/.local/lib/python3.8/site-packages/sqlalchemy/pool/base.py", line 327, in connect
    return _ConnectionFairy._checkout(self)
  File "/home/airflow/.local/lib/python3.8/site-packages/sqlalchemy/pool/base.py", line 894, in _checkout
    fairy = _ConnectionRecord.checkout(pool)
  File "/home/airflow/.local/lib/python3.8/site-packages/sqlalchemy/pool/base.py", line 493, in checkout
    rec = pool._do_get()
  File "/home/airflow/.local/lib/python3.8/site-packages/sqlalchemy/pool/impl.py", line 256, in _do_get
    return self._create_connection()
  File "/home/airflow/.local/lib/python3.8/site-packages/sqlalchemy/pool/base.py", line 273, in _create_connection
    return _ConnectionRecord(self)
  File "/home/airflow/.local/lib/python3.8/site-packages/sqlalchemy/pool/base.py", line 388, in __init__
    self.__connect()
  File "/home/airflow/.local/lib/python3.8/site-packages/sqlalchemy/pool/base.py", line 691, in __connect
    pool.logger.debug("Error on connect(): %s", e)
  File "/home/airflow/.local/lib/python3.8/site-packages/sqlalchemy/util/langhelpers.py", line 70, in __exit__
    compat.raise_(
  File "/home/airflow/.local/lib/python3.8/site-packages/sqlalchemy/util/compat.py", line 211, in raise_
    raise exception
  File "/home/airflow/.local/lib/python3.8/site-packages/sqlalchemy/pool/base.py", line 686, in __connect
    self.dbapi_connection = connection = pool._invoke_creator(self)
  File "/home/airflow/.local/lib/python3.8/site-packages/sqlalchemy/engine/create.py", line 574, in connect
    return dialect.connect(*cargs, **cparams)
  File "/home/airflow/.local/lib/python3.8/site-packages/sqlalchemy/engine/default.py", line 598, in connect
    return self.dbapi.connect(*cargs, **cparams)
  File "/home/airflow/.local/lib/python3.8/site-packages/psycopg2/__init__.py", line 122, in connect
    conn = _connect(dsn, connection_factory=connection_factory, **kwasync)
sqlalchemy.exc.OperationalError: (psycopg2.OperationalError) could not translate host name "postgres" to address: Temporary failure in name resolution

(Background on this error at: https://sqlalche.me/e/14/e3q8)
[2023-11-11T07:15:27.213+0000] {job.py:219} ERROR - Job heartbeat got an exception
Traceback (most recent call last):
  File "/home/airflow/.local/lib/python3.8/site-packages/sqlalchemy/engine/base.py", line 3371, in _wrap_pool_connect
    return fn()
  File "/home/airflow/.local/lib/python3.8/site-packages/sqlalchemy/pool/base.py", line 327, in connect
    return _ConnectionFairy._checkout(self)
  File "/home/airflow/.local/lib/python3.8/site-packages/sqlalchemy/pool/base.py", line 894, in _checkout
    fairy = _ConnectionRecord.checkout(pool)
  File "/home/airflow/.local/lib/python3.8/site-packages/sqlalchemy/pool/base.py", line 493, in checkout
    rec = pool._do_get()
  File "/home/airflow/.local/lib/python3.8/site-packages/sqlalchemy/pool/impl.py", line 256, in _do_get
    return self._create_connection()
  File "/home/airflow/.local/lib/python3.8/site-packages/sqlalchemy/pool/base.py", line 273, in _create_connection
    return _ConnectionRecord(self)
  File "/home/airflow/.local/lib/python3.8/site-packages/sqlalchemy/pool/base.py", line 388, in __init__
    self.__connect()
  File "/home/airflow/.local/lib/python3.8/site-packages/sqlalchemy/pool/base.py", line 691, in __connect
    pool.logger.debug("Error on connect(): %s", e)
  File "/home/airflow/.local/lib/python3.8/site-packages/sqlalchemy/util/langhelpers.py", line 70, in __exit__
    compat.raise_(
  File "/home/airflow/.local/lib/python3.8/site-packages/sqlalchemy/util/compat.py", line 211, in raise_
    raise exception
  File "/home/airflow/.local/lib/python3.8/site-packages/sqlalchemy/pool/base.py", line 686, in __connect
    self.dbapi_connection = connection = pool._invoke_creator(self)
  File "/home/airflow/.local/lib/python3.8/site-packages/sqlalchemy/engine/create.py", line 574, in connect
    return dialect.connect(*cargs, **cparams)
  File "/home/airflow/.local/lib/python3.8/site-packages/sqlalchemy/engine/default.py", line 598, in connect
    return self.dbapi.connect(*cargs, **cparams)
  File "/home/airflow/.local/lib/python3.8/site-packages/psycopg2/__init__.py", line 122, in connect
    conn = _connect(dsn, connection_factory=connection_factory, **kwasync)
psycopg2.OperationalError: could not translate host name "postgres" to address: Temporary failure in name resolution


The above exception was the direct cause of the following exception:

Traceback (most recent call last):
  File "/home/airflow/.local/lib/python3.8/site-packages/airflow/jobs/job.py", line 190, in heartbeat
    session.merge(self)
  File "/home/airflow/.local/lib/python3.8/site-packages/sqlalchemy/orm/session.py", line 3056, in merge
    return self._merge(
  File "/home/airflow/.local/lib/python3.8/site-packages/sqlalchemy/orm/session.py", line 3136, in _merge
    merged = self.get(
  File "/home/airflow/.local/lib/python3.8/site-packages/sqlalchemy/orm/session.py", line 2853, in get
    return self._get_impl(
  File "/home/airflow/.local/lib/python3.8/site-packages/sqlalchemy/orm/session.py", line 2975, in _get_impl
    return db_load_fn(
  File "/home/airflow/.local/lib/python3.8/site-packages/sqlalchemy/orm/loading.py", line 530, in load_on_pk_identity
    session.execute(
  File "/home/airflow/.local/lib/python3.8/site-packages/sqlalchemy/orm/session.py", line 1716, in execute
    conn = self._connection_for_bind(bind)
  File "/home/airflow/.local/lib/python3.8/site-packages/sqlalchemy/orm/session.py", line 1555, in _connection_for_bind
    return self._transaction._connection_for_bind(
  File "/home/airflow/.local/lib/python3.8/site-packages/sqlalchemy/orm/session.py", line 750, in _connection_for_bind
    conn = bind.connect()
  File "/home/airflow/.local/lib/python3.8/site-packages/sqlalchemy/future/engine.py", line 406, in connect
    return super(Engine, self).connect()
  File "/home/airflow/.local/lib/python3.8/site-packages/sqlalchemy/engine/base.py", line 3325, in connect
    return self._connection_cls(self, close_with_result=close_with_result)
  File "/home/airflow/.local/lib/python3.8/site-packages/sqlalchemy/engine/base.py", line 96, in __init__
    else engine.raw_connection()
  File "/home/airflow/.local/lib/python3.8/site-packages/sqlalchemy/engine/base.py", line 3404, in raw_connection
    return self._wrap_pool_connect(self.pool.connect, _connection)
  File "/home/airflow/.local/lib/python3.8/site-packages/sqlalchemy/engine/base.py", line 3374, in _wrap_pool_connect
    Connection._handle_dbapi_exception_noconnection(
  File "/home/airflow/.local/lib/python3.8/site-packages/sqlalchemy/engine/base.py", line 2208, in _handle_dbapi_exception_noconnection
    util.raise_(
  File "/home/airflow/.local/lib/python3.8/site-packages/sqlalchemy/util/compat.py", line 211, in raise_
    raise exception
  File "/home/airflow/.local/lib/python3.8/site-packages/sqlalchemy/engine/base.py", line 3371, in _wrap_pool_connect
    return fn()
  File "/home/airflow/.local/lib/python3.8/site-packages/sqlalchemy/pool/base.py", line 327, in connect
    return _ConnectionFairy._checkout(self)
  File "/home/airflow/.local/lib/python3.8/site-packages/sqlalchemy/pool/base.py", line 894, in _checkout
    fairy = _ConnectionRecord.checkout(pool)
  File "/home/airflow/.local/lib/python3.8/site-packages/sqlalchemy/pool/base.py", line 493, in checkout
    rec = pool._do_get()
  File "/home/airflow/.local/lib/python3.8/site-packages/sqlalchemy/pool/impl.py", line 256, in _do_get
    return self._create_connection()
  File "/home/airflow/.local/lib/python3.8/site-packages/sqlalchemy/pool/base.py", line 273, in _create_connection
    return _ConnectionRecord(self)
  File "/home/airflow/.local/lib/python3.8/site-packages/sqlalchemy/pool/base.py", line 388, in __init__
    self.__connect()
  File "/home/airflow/.local/lib/python3.8/site-packages/sqlalchemy/pool/base.py", line 691, in __connect
    pool.logger.debug("Error on connect(): %s", e)
  File "/home/airflow/.local/lib/python3.8/site-packages/sqlalchemy/util/langhelpers.py", line 70, in __exit__
    compat.raise_(
  File "/home/airflow/.local/lib/python3.8/site-packages/sqlalchemy/util/compat.py", line 211, in raise_
    raise exception
  File "/home/airflow/.local/lib/python3.8/site-packages/sqlalchemy/pool/base.py", line 686, in __connect
    self.dbapi_connection = connection = pool._invoke_creator(self)
  File "/home/airflow/.local/lib/python3.8/site-packages/sqlalchemy/engine/create.py", line 574, in connect
    return dialect.connect(*cargs, **cparams)
  File "/home/airflow/.local/lib/python3.8/site-packages/sqlalchemy/engine/default.py", line 598, in connect
    return self.dbapi.connect(*cargs, **cparams)
  File "/home/airflow/.local/lib/python3.8/site-packages/psycopg2/__init__.py", line 122, in connect
    conn = _connect(dsn, connection_factory=connection_factory, **kwasync)
sqlalchemy.exc.OperationalError: (psycopg2.OperationalError) could not translate host name "postgres" to address: Temporary failure in name resolution

(Background on this error at: https://sqlalche.me/e/14/e3q8)
[2023-11-11T07:15:43.359+0000] {job.py:219} ERROR - Job heartbeat got an exception
Traceback (most recent call last):
  File "/home/airflow/.local/lib/python3.8/site-packages/sqlalchemy/engine/base.py", line 3371, in _wrap_pool_connect
    return fn()
  File "/home/airflow/.local/lib/python3.8/site-packages/sqlalchemy/pool/base.py", line 327, in connect
    return _ConnectionFairy._checkout(self)
  File "/home/airflow/.local/lib/python3.8/site-packages/sqlalchemy/pool/base.py", line 894, in _checkout
    fairy = _ConnectionRecord.checkout(pool)
  File "/home/airflow/.local/lib/python3.8/site-packages/sqlalchemy/pool/base.py", line 493, in checkout
    rec = pool._do_get()
  File "/home/airflow/.local/lib/python3.8/site-packages/sqlalchemy/pool/impl.py", line 256, in _do_get
    return self._create_connection()
  File "/home/airflow/.local/lib/python3.8/site-packages/sqlalchemy/pool/base.py", line 273, in _create_connection
    return _ConnectionRecord(self)
  File "/home/airflow/.local/lib/python3.8/site-packages/sqlalchemy/pool/base.py", line 388, in __init__
    self.__connect()
  File "/home/airflow/.local/lib/python3.8/site-packages/sqlalchemy/pool/base.py", line 691, in __connect
    pool.logger.debug("Error on connect(): %s", e)
  File "/home/airflow/.local/lib/python3.8/site-packages/sqlalchemy/util/langhelpers.py", line 70, in __exit__
    compat.raise_(
  File "/home/airflow/.local/lib/python3.8/site-packages/sqlalchemy/util/compat.py", line 211, in raise_
    raise exception
  File "/home/airflow/.local/lib/python3.8/site-packages/sqlalchemy/pool/base.py", line 686, in __connect
    self.dbapi_connection = connection = pool._invoke_creator(self)
  File "/home/airflow/.local/lib/python3.8/site-packages/sqlalchemy/engine/create.py", line 574, in connect
    return dialect.connect(*cargs, **cparams)
  File "/home/airflow/.local/lib/python3.8/site-packages/sqlalchemy/engine/default.py", line 598, in connect
    return self.dbapi.connect(*cargs, **cparams)
  File "/home/airflow/.local/lib/python3.8/site-packages/psycopg2/__init__.py", line 122, in connect
    conn = _connect(dsn, connection_factory=connection_factory, **kwasync)
psycopg2.OperationalError: could not translate host name "postgres" to address: Temporary failure in name resolution


The above exception was the direct cause of the following exception:

Traceback (most recent call last):
  File "/home/airflow/.local/lib/python3.8/site-packages/airflow/jobs/job.py", line 190, in heartbeat
    session.merge(self)
  File "/home/airflow/.local/lib/python3.8/site-packages/sqlalchemy/orm/session.py", line 3056, in merge
    return self._merge(
  File "/home/airflow/.local/lib/python3.8/site-packages/sqlalchemy/orm/session.py", line 3136, in _merge
    merged = self.get(
  File "/home/airflow/.local/lib/python3.8/site-packages/sqlalchemy/orm/session.py", line 2853, in get
    return self._get_impl(
  File "/home/airflow/.local/lib/python3.8/site-packages/sqlalchemy/orm/session.py", line 2975, in _get_impl
    return db_load_fn(
  File "/home/airflow/.local/lib/python3.8/site-packages/sqlalchemy/orm/loading.py", line 530, in load_on_pk_identity
    session.execute(
  File "/home/airflow/.local/lib/python3.8/site-packages/sqlalchemy/orm/session.py", line 1716, in execute
    conn = self._connection_for_bind(bind)
  File "/home/airflow/.local/lib/python3.8/site-packages/sqlalchemy/orm/session.py", line 1555, in _connection_for_bind
    return self._transaction._connection_for_bind(
  File "/home/airflow/.local/lib/python3.8/site-packages/sqlalchemy/orm/session.py", line 750, in _connection_for_bind
    conn = bind.connect()
  File "/home/airflow/.local/lib/python3.8/site-packages/sqlalchemy/future/engine.py", line 406, in connect
    return super(Engine, self).connect()
  File "/home/airflow/.local/lib/python3.8/site-packages/sqlalchemy/engine/base.py", line 3325, in connect
    return self._connection_cls(self, close_with_result=close_with_result)
  File "/home/airflow/.local/lib/python3.8/site-packages/sqlalchemy/engine/base.py", line 96, in __init__
    else engine.raw_connection()
  File "/home/airflow/.local/lib/python3.8/site-packages/sqlalchemy/engine/base.py", line 3404, in raw_connection
    return self._wrap_pool_connect(self.pool.connect, _connection)
  File "/home/airflow/.local/lib/python3.8/site-packages/sqlalchemy/engine/base.py", line 3374, in _wrap_pool_connect
    Connection._handle_dbapi_exception_noconnection(
  File "/home/airflow/.local/lib/python3.8/site-packages/sqlalchemy/engine/base.py", line 2208, in _handle_dbapi_exception_noconnection
    util.raise_(
  File "/home/airflow/.local/lib/python3.8/site-packages/sqlalchemy/util/compat.py", line 211, in raise_
    raise exception
  File "/home/airflow/.local/lib/python3.8/site-packages/sqlalchemy/engine/base.py", line 3371, in _wrap_pool_connect
    return fn()
  File "/home/airflow/.local/lib/python3.8/site-packages/sqlalchemy/pool/base.py", line 327, in connect
    return _ConnectionFairy._checkout(self)
  File "/home/airflow/.local/lib/python3.8/site-packages/sqlalchemy/pool/base.py", line 894, in _checkout
    fairy = _ConnectionRecord.checkout(pool)
  File "/home/airflow/.local/lib/python3.8/site-packages/sqlalchemy/pool/base.py", line 493, in checkout
    rec = pool._do_get()
  File "/home/airflow/.local/lib/python3.8/site-packages/sqlalchemy/pool/impl.py", line 256, in _do_get
    return self._create_connection()
  File "/home/airflow/.local/lib/python3.8/site-packages/sqlalchemy/pool/base.py", line 273, in _create_connection
    return _ConnectionRecord(self)
  File "/home/airflow/.local/lib/python3.8/site-packages/sqlalchemy/pool/base.py", line 388, in __init__
    self.__connect()
  File "/home/airflow/.local/lib/python3.8/site-packages/sqlalchemy/pool/base.py", line 691, in __connect
    pool.logger.debug("Error on connect(): %s", e)
  File "/home/airflow/.local/lib/python3.8/site-packages/sqlalchemy/util/langhelpers.py", line 70, in __exit__
    compat.raise_(
  File "/home/airflow/.local/lib/python3.8/site-packages/sqlalchemy/util/compat.py", line 211, in raise_
    raise exception
  File "/home/airflow/.local/lib/python3.8/site-packages/sqlalchemy/pool/base.py", line 686, in __connect
    self.dbapi_connection = connection = pool._invoke_creator(self)
  File "/home/airflow/.local/lib/python3.8/site-packages/sqlalchemy/engine/create.py", line 574, in connect
    return dialect.connect(*cargs, **cparams)
  File "/home/airflow/.local/lib/python3.8/site-packages/sqlalchemy/engine/default.py", line 598, in connect
    return self.dbapi.connect(*cargs, **cparams)
  File "/home/airflow/.local/lib/python3.8/site-packages/psycopg2/__init__.py", line 122, in connect
    conn = _connect(dsn, connection_factory=connection_factory, **kwasync)
sqlalchemy.exc.OperationalError: (psycopg2.OperationalError) could not translate host name "postgres" to address: Temporary failure in name resolution

(Background on this error at: https://sqlalche.me/e/14/e3q8)
[2023-11-11T07:16:04.981+0000] {local_task_job_runner.py:115} ERROR - Received SIGTERM. Terminating subprocesses
[2023-11-11T07:16:05.416+0000] {process_utils.py:131} INFO - Sending 15 to group 252. PIDs of all processes in the group: [252]
[2023-11-11T07:16:05.454+0000] {process_utils.py:86} INFO - Sending the signal 15 to group 252
[2023-11-11T07:16:05.563+0000] {taskinstance.py:1632} ERROR - Received SIGTERM. Terminating subprocesses.
[2023-11-11T07:16:07.581+0000] {taskinstance.py:1937} ERROR - Task failed with exception
Traceback (most recent call last):
  File "/home/airflow/.local/lib/python3.8/site-packages/airflow/operators/python.py", line 192, in execute
    return_value = self.execute_callable()
  File "/home/airflow/.local/lib/python3.8/site-packages/airflow/operators/python.py", line 209, in execute_callable
    return self.python_callable(*self.op_args, **self.op_kwargs)
  File "/opt/airflow/dags/src/datapreprocessing.py", line 30, in split_dataset
    X_test.to_csv(os.path.join(os.path.dirname(__file__), "../data/X_test.csv"), index=False)
  File "/home/airflow/.local/lib/python3.8/site-packages/pandas/core/generic.py", line 3772, in to_csv
    return DataFrameRenderer(formatter).to_csv(
  File "/home/airflow/.local/lib/python3.8/site-packages/pandas/io/formats/format.py", line 1186, in to_csv
    csv_formatter.save()
  File "/home/airflow/.local/lib/python3.8/site-packages/pandas/io/formats/csvs.py", line 259, in save
    self._save()
  File "/home/airflow/.local/lib/python3.8/site-packages/pandas/io/formats/csvs.py", line 264, in _save
    self._save_body()
  File "/home/airflow/.local/lib/python3.8/site-packages/pandas/io/formats/csvs.py", line 302, in _save_body
    self._save_chunk(start_i, end_i)
  File "/home/airflow/.local/lib/python3.8/site-packages/pandas/io/formats/csvs.py", line 313, in _save_chunk
    libwriters.write_csv_rows(
  File "pandas/_libs/writers.pyx", line 72, in pandas._libs.writers.write_csv_rows
  File "/home/airflow/.local/lib/python3.8/site-packages/airflow/models/taskinstance.py", line 1634, in signal_handler
    raise AirflowException("Task received SIGTERM signal")
airflow.exceptions.AirflowException: Task received SIGTERM signal
[2023-11-11T07:16:08.017+0000] {taskinstance.py:1400} INFO - Marking task as UP_FOR_RETRY. dag_id=preprocessing_v1, task_id=split_task, execution_date=20231109T000000, start_date=20231111T071435, end_date=20231111T071607
[2023-11-11T07:16:08.331+0000] {standard_task_runner.py:104} ERROR - Failed to execute job 6 for task split_task (Task received SIGTERM signal; 252)
[2023-11-11T07:16:08.679+0000] {process_utils.py:79} INFO - Process psutil.Process(pid=252, status='terminated', exitcode=1, started='07:14:34') (252) terminated with exit code 1
[2023-11-11T07:16:08.792+0000] {local_task_job_runner.py:228} INFO - Task exited with return code 143
[2023-11-11T07:16:10.594+0000] {taskinstance.py:2778} INFO - 0 downstream tasks scheduled from follow-on schedule check
[2023-11-11T07:17:53.004+0000] {taskinstance.py:1159} INFO - Dependencies all met for dep_context=non-requeueable deps ti=<TaskInstance: preprocessing_v1.split_task scheduled__2023-11-09T00:00:00+00:00 [queued]>
[2023-11-11T07:17:53.012+0000] {taskinstance.py:1159} INFO - Dependencies all met for dep_context=requeueable deps ti=<TaskInstance: preprocessing_v1.split_task scheduled__2023-11-09T00:00:00+00:00 [queued]>
[2023-11-11T07:17:53.014+0000] {taskinstance.py:1361} INFO - Starting attempt 1 of 6
[2023-11-11T07:17:53.022+0000] {taskinstance.py:1382} INFO - Executing <Task(PythonOperator): split_task> on 2023-11-09 00:00:00+00:00
[2023-11-11T07:17:53.042+0000] {standard_task_runner.py:57} INFO - Started process 252 to run task
[2023-11-11T07:17:53.049+0000] {standard_task_runner.py:84} INFO - Running: ['***', 'tasks', 'run', 'preprocessing_v1', 'split_task', 'scheduled__2023-11-09T00:00:00+00:00', '--job-id', '4', '--raw', '--subdir', 'DAGS_FOLDER/***_code.py', '--cfg-path', '/tmp/tmpprwcnjhs']
[2023-11-11T07:17:53.052+0000] {standard_task_runner.py:85} INFO - Job 4: Subtask split_task
[2023-11-11T07:17:53.116+0000] {task_command.py:416} INFO - Running <TaskInstance: preprocessing_v1.split_task scheduled__2023-11-09T00:00:00+00:00 [running]> on host 2c83865699e0
[2023-11-11T07:17:53.199+0000] {taskinstance.py:1662} INFO - Exporting env vars: AIRFLOW_CTX_DAG_OWNER='Team 3' AIRFLOW_CTX_DAG_ID='preprocessing_v1' AIRFLOW_CTX_TASK_ID='split_task' AIRFLOW_CTX_EXECUTION_DATE='2023-11-09T00:00:00+00:00' AIRFLOW_CTX_TRY_NUMBER='1' AIRFLOW_CTX_DAG_RUN_ID='scheduled__2023-11-09T00:00:00+00:00'
[2023-11-11T07:17:56.716+0000] {python.py:194} INFO - Done. Returned value was: 1
[2023-11-11T07:17:56.776+0000] {taskinstance.py:1400} INFO - Marking task as SUCCESS. dag_id=preprocessing_v1, task_id=split_task, execution_date=20231109T000000, start_date=20231111T071753, end_date=20231111T071756
[2023-11-11T07:17:56.827+0000] {local_task_job_runner.py:228} INFO - Task exited with return code 0
[2023-11-11T07:17:56.902+0000] {taskinstance.py:2778} INFO - 0 downstream tasks scheduled from follow-on schedule check
