[2023-11-11T07:14:35.483+0000] {taskinstance.py:1159} INFO - Dependencies all met for dep_context=non-requeueable deps ti=<TaskInstance: preprocessing_v1.split_task manual__2023-11-11T07:14:32.276000+00:00 [queued]>
[2023-11-11T07:14:35.494+0000] {taskinstance.py:1159} INFO - Dependencies all met for dep_context=requeueable deps ti=<TaskInstance: preprocessing_v1.split_task manual__2023-11-11T07:14:32.276000+00:00 [queued]>
[2023-11-11T07:14:35.494+0000] {taskinstance.py:1361} INFO - Starting attempt 1 of 6
[2023-11-11T07:14:35.514+0000] {taskinstance.py:1382} INFO - Executing <Task(PythonOperator): split_task> on 2023-11-11 07:14:32.276000+00:00
[2023-11-11T07:14:35.537+0000] {standard_task_runner.py:57} INFO - Started process 254 to run task
[2023-11-11T07:14:35.562+0000] {standard_task_runner.py:84} INFO - Running: ['***', 'tasks', 'run', 'preprocessing_v1', 'split_task', 'manual__2023-11-11T07:14:32.276000+00:00', '--job-id', '3', '--raw', '--subdir', 'DAGS_FOLDER/***_code.py', '--cfg-path', '/tmp/tmp6scnfa0u']
[2023-11-11T07:14:35.579+0000] {standard_task_runner.py:85} INFO - Job 3: Subtask split_task
[2023-11-11T07:14:35.811+0000] {task_command.py:416} INFO - Running <TaskInstance: preprocessing_v1.split_task manual__2023-11-11T07:14:32.276000+00:00 [running]> on host ab7bd6d8471a
[2023-11-11T07:14:36.179+0000] {taskinstance.py:1662} INFO - Exporting env vars: AIRFLOW_CTX_DAG_OWNER='Team 3' AIRFLOW_CTX_DAG_ID='preprocessing_v1' AIRFLOW_CTX_TASK_ID='split_task' AIRFLOW_CTX_EXECUTION_DATE='2023-11-11T07:14:32.276000+00:00' AIRFLOW_CTX_TRY_NUMBER='1' AIRFLOW_CTX_DAG_RUN_ID='manual__2023-11-11T07:14:32.276000+00:00'
[2023-11-11T07:14:56.841+0000] {job.py:219} ERROR - Job heartbeat got an exception
Traceback (most recent call last):
  File "/home/airflow/.local/lib/python3.8/site-packages/sqlalchemy/engine/base.py", line 3371, in _wrap_pool_connect
    return fn()
  File "/home/airflow/.local/lib/python3.8/site-packages/sqlalchemy/pool/base.py", line 327, in connect
    return _ConnectionFairy._checkout(self)
  File "/home/airflow/.local/lib/python3.8/site-packages/sqlalchemy/pool/base.py", line 894, in _checkout
    fairy = _ConnectionRecord.checkout(pool)
  File "/home/airflow/.local/lib/python3.8/site-packages/sqlalchemy/pool/base.py", line 493, in checkout
    rec = pool._do_get()
  File "/home/airflow/.local/lib/python3.8/site-packages/sqlalchemy/pool/impl.py", line 256, in _do_get
    return self._create_connection()
  File "/home/airflow/.local/lib/python3.8/site-packages/sqlalchemy/pool/base.py", line 273, in _create_connection
    return _ConnectionRecord(self)
  File "/home/airflow/.local/lib/python3.8/site-packages/sqlalchemy/pool/base.py", line 388, in __init__
    self.__connect()
  File "/home/airflow/.local/lib/python3.8/site-packages/sqlalchemy/pool/base.py", line 691, in __connect
    pool.logger.debug("Error on connect(): %s", e)
  File "/home/airflow/.local/lib/python3.8/site-packages/sqlalchemy/util/langhelpers.py", line 70, in __exit__
    compat.raise_(
  File "/home/airflow/.local/lib/python3.8/site-packages/sqlalchemy/util/compat.py", line 211, in raise_
    raise exception
  File "/home/airflow/.local/lib/python3.8/site-packages/sqlalchemy/pool/base.py", line 686, in __connect
    self.dbapi_connection = connection = pool._invoke_creator(self)
  File "/home/airflow/.local/lib/python3.8/site-packages/sqlalchemy/engine/create.py", line 574, in connect
    return dialect.connect(*cargs, **cparams)
  File "/home/airflow/.local/lib/python3.8/site-packages/sqlalchemy/engine/default.py", line 598, in connect
    return self.dbapi.connect(*cargs, **cparams)
  File "/home/airflow/.local/lib/python3.8/site-packages/psycopg2/__init__.py", line 122, in connect
    conn = _connect(dsn, connection_factory=connection_factory, **kwasync)
psycopg2.OperationalError: could not translate host name "postgres" to address: Temporary failure in name resolution


The above exception was the direct cause of the following exception:

Traceback (most recent call last):
  File "/home/airflow/.local/lib/python3.8/site-packages/airflow/jobs/job.py", line 190, in heartbeat
    session.merge(self)
  File "/home/airflow/.local/lib/python3.8/site-packages/sqlalchemy/orm/session.py", line 3056, in merge
    return self._merge(
  File "/home/airflow/.local/lib/python3.8/site-packages/sqlalchemy/orm/session.py", line 3136, in _merge
    merged = self.get(
  File "/home/airflow/.local/lib/python3.8/site-packages/sqlalchemy/orm/session.py", line 2853, in get
    return self._get_impl(
  File "/home/airflow/.local/lib/python3.8/site-packages/sqlalchemy/orm/session.py", line 2975, in _get_impl
    return db_load_fn(
  File "/home/airflow/.local/lib/python3.8/site-packages/sqlalchemy/orm/loading.py", line 530, in load_on_pk_identity
    session.execute(
  File "/home/airflow/.local/lib/python3.8/site-packages/sqlalchemy/orm/session.py", line 1716, in execute
    conn = self._connection_for_bind(bind)
  File "/home/airflow/.local/lib/python3.8/site-packages/sqlalchemy/orm/session.py", line 1555, in _connection_for_bind
    return self._transaction._connection_for_bind(
  File "/home/airflow/.local/lib/python3.8/site-packages/sqlalchemy/orm/session.py", line 750, in _connection_for_bind
    conn = bind.connect()
  File "/home/airflow/.local/lib/python3.8/site-packages/sqlalchemy/future/engine.py", line 406, in connect
    return super(Engine, self).connect()
  File "/home/airflow/.local/lib/python3.8/site-packages/sqlalchemy/engine/base.py", line 3325, in connect
    return self._connection_cls(self, close_with_result=close_with_result)
  File "/home/airflow/.local/lib/python3.8/site-packages/sqlalchemy/engine/base.py", line 96, in __init__
    else engine.raw_connection()
  File "/home/airflow/.local/lib/python3.8/site-packages/sqlalchemy/engine/base.py", line 3404, in raw_connection
    return self._wrap_pool_connect(self.pool.connect, _connection)
  File "/home/airflow/.local/lib/python3.8/site-packages/sqlalchemy/engine/base.py", line 3374, in _wrap_pool_connect
    Connection._handle_dbapi_exception_noconnection(
  File "/home/airflow/.local/lib/python3.8/site-packages/sqlalchemy/engine/base.py", line 2208, in _handle_dbapi_exception_noconnection
    util.raise_(
  File "/home/airflow/.local/lib/python3.8/site-packages/sqlalchemy/util/compat.py", line 211, in raise_
    raise exception
  File "/home/airflow/.local/lib/python3.8/site-packages/sqlalchemy/engine/base.py", line 3371, in _wrap_pool_connect
    return fn()
  File "/home/airflow/.local/lib/python3.8/site-packages/sqlalchemy/pool/base.py", line 327, in connect
    return _ConnectionFairy._checkout(self)
  File "/home/airflow/.local/lib/python3.8/site-packages/sqlalchemy/pool/base.py", line 894, in _checkout
    fairy = _ConnectionRecord.checkout(pool)
  File "/home/airflow/.local/lib/python3.8/site-packages/sqlalchemy/pool/base.py", line 493, in checkout
    rec = pool._do_get()
  File "/home/airflow/.local/lib/python3.8/site-packages/sqlalchemy/pool/impl.py", line 256, in _do_get
    return self._create_connection()
  File "/home/airflow/.local/lib/python3.8/site-packages/sqlalchemy/pool/base.py", line 273, in _create_connection
    return _ConnectionRecord(self)
  File "/home/airflow/.local/lib/python3.8/site-packages/sqlalchemy/pool/base.py", line 388, in __init__
    self.__connect()
  File "/home/airflow/.local/lib/python3.8/site-packages/sqlalchemy/pool/base.py", line 691, in __connect
    pool.logger.debug("Error on connect(): %s", e)
  File "/home/airflow/.local/lib/python3.8/site-packages/sqlalchemy/util/langhelpers.py", line 70, in __exit__
    compat.raise_(
  File "/home/airflow/.local/lib/python3.8/site-packages/sqlalchemy/util/compat.py", line 211, in raise_
    raise exception
  File "/home/airflow/.local/lib/python3.8/site-packages/sqlalchemy/pool/base.py", line 686, in __connect
    self.dbapi_connection = connection = pool._invoke_creator(self)
  File "/home/airflow/.local/lib/python3.8/site-packages/sqlalchemy/engine/create.py", line 574, in connect
    return dialect.connect(*cargs, **cparams)
  File "/home/airflow/.local/lib/python3.8/site-packages/sqlalchemy/engine/default.py", line 598, in connect
    return self.dbapi.connect(*cargs, **cparams)
  File "/home/airflow/.local/lib/python3.8/site-packages/psycopg2/__init__.py", line 122, in connect
    conn = _connect(dsn, connection_factory=connection_factory, **kwasync)
sqlalchemy.exc.OperationalError: (psycopg2.OperationalError) could not translate host name "postgres" to address: Temporary failure in name resolution

(Background on this error at: https://sqlalche.me/e/14/e3q8)
[2023-11-11T07:15:23.477+0000] {job.py:219} ERROR - Job heartbeat got an exception
Traceback (most recent call last):
  File "/home/airflow/.local/lib/python3.8/site-packages/sqlalchemy/engine/base.py", line 3371, in _wrap_pool_connect
    return fn()
  File "/home/airflow/.local/lib/python3.8/site-packages/sqlalchemy/pool/base.py", line 327, in connect
    return _ConnectionFairy._checkout(self)
  File "/home/airflow/.local/lib/python3.8/site-packages/sqlalchemy/pool/base.py", line 894, in _checkout
    fairy = _ConnectionRecord.checkout(pool)
  File "/home/airflow/.local/lib/python3.8/site-packages/sqlalchemy/pool/base.py", line 493, in checkout
    rec = pool._do_get()
  File "/home/airflow/.local/lib/python3.8/site-packages/sqlalchemy/pool/impl.py", line 256, in _do_get
    return self._create_connection()
  File "/home/airflow/.local/lib/python3.8/site-packages/sqlalchemy/pool/base.py", line 273, in _create_connection
    return _ConnectionRecord(self)
  File "/home/airflow/.local/lib/python3.8/site-packages/sqlalchemy/pool/base.py", line 388, in __init__
    self.__connect()
  File "/home/airflow/.local/lib/python3.8/site-packages/sqlalchemy/pool/base.py", line 691, in __connect
    pool.logger.debug("Error on connect(): %s", e)
  File "/home/airflow/.local/lib/python3.8/site-packages/sqlalchemy/util/langhelpers.py", line 70, in __exit__
    compat.raise_(
  File "/home/airflow/.local/lib/python3.8/site-packages/sqlalchemy/util/compat.py", line 211, in raise_
    raise exception
  File "/home/airflow/.local/lib/python3.8/site-packages/sqlalchemy/pool/base.py", line 686, in __connect
    self.dbapi_connection = connection = pool._invoke_creator(self)
  File "/home/airflow/.local/lib/python3.8/site-packages/sqlalchemy/engine/create.py", line 574, in connect
    return dialect.connect(*cargs, **cparams)
  File "/home/airflow/.local/lib/python3.8/site-packages/sqlalchemy/engine/default.py", line 598, in connect
    return self.dbapi.connect(*cargs, **cparams)
  File "/home/airflow/.local/lib/python3.8/site-packages/psycopg2/__init__.py", line 122, in connect
    conn = _connect(dsn, connection_factory=connection_factory, **kwasync)
psycopg2.OperationalError: could not translate host name "postgres" to address: Temporary failure in name resolution


The above exception was the direct cause of the following exception:

Traceback (most recent call last):
  File "/home/airflow/.local/lib/python3.8/site-packages/airflow/jobs/job.py", line 190, in heartbeat
    session.merge(self)
  File "/home/airflow/.local/lib/python3.8/site-packages/sqlalchemy/orm/session.py", line 3056, in merge
    return self._merge(
  File "/home/airflow/.local/lib/python3.8/site-packages/sqlalchemy/orm/session.py", line 3136, in _merge
    merged = self.get(
  File "/home/airflow/.local/lib/python3.8/site-packages/sqlalchemy/orm/session.py", line 2853, in get
    return self._get_impl(
  File "/home/airflow/.local/lib/python3.8/site-packages/sqlalchemy/orm/session.py", line 2975, in _get_impl
    return db_load_fn(
  File "/home/airflow/.local/lib/python3.8/site-packages/sqlalchemy/orm/loading.py", line 530, in load_on_pk_identity
    session.execute(
  File "/home/airflow/.local/lib/python3.8/site-packages/sqlalchemy/orm/session.py", line 1716, in execute
    conn = self._connection_for_bind(bind)
  File "/home/airflow/.local/lib/python3.8/site-packages/sqlalchemy/orm/session.py", line 1555, in _connection_for_bind
    return self._transaction._connection_for_bind(
  File "/home/airflow/.local/lib/python3.8/site-packages/sqlalchemy/orm/session.py", line 750, in _connection_for_bind
    conn = bind.connect()
  File "/home/airflow/.local/lib/python3.8/site-packages/sqlalchemy/future/engine.py", line 406, in connect
    return super(Engine, self).connect()
  File "/home/airflow/.local/lib/python3.8/site-packages/sqlalchemy/engine/base.py", line 3325, in connect
    return self._connection_cls(self, close_with_result=close_with_result)
  File "/home/airflow/.local/lib/python3.8/site-packages/sqlalchemy/engine/base.py", line 96, in __init__
    else engine.raw_connection()
  File "/home/airflow/.local/lib/python3.8/site-packages/sqlalchemy/engine/base.py", line 3404, in raw_connection
    return self._wrap_pool_connect(self.pool.connect, _connection)
  File "/home/airflow/.local/lib/python3.8/site-packages/sqlalchemy/engine/base.py", line 3374, in _wrap_pool_connect
    Connection._handle_dbapi_exception_noconnection(
  File "/home/airflow/.local/lib/python3.8/site-packages/sqlalchemy/engine/base.py", line 2208, in _handle_dbapi_exception_noconnection
    util.raise_(
  File "/home/airflow/.local/lib/python3.8/site-packages/sqlalchemy/util/compat.py", line 211, in raise_
    raise exception
  File "/home/airflow/.local/lib/python3.8/site-packages/sqlalchemy/engine/base.py", line 3371, in _wrap_pool_connect
    return fn()
  File "/home/airflow/.local/lib/python3.8/site-packages/sqlalchemy/pool/base.py", line 327, in connect
    return _ConnectionFairy._checkout(self)
  File "/home/airflow/.local/lib/python3.8/site-packages/sqlalchemy/pool/base.py", line 894, in _checkout
    fairy = _ConnectionRecord.checkout(pool)
  File "/home/airflow/.local/lib/python3.8/site-packages/sqlalchemy/pool/base.py", line 493, in checkout
    rec = pool._do_get()
  File "/home/airflow/.local/lib/python3.8/site-packages/sqlalchemy/pool/impl.py", line 256, in _do_get
    return self._create_connection()
  File "/home/airflow/.local/lib/python3.8/site-packages/sqlalchemy/pool/base.py", line 273, in _create_connection
    return _ConnectionRecord(self)
  File "/home/airflow/.local/lib/python3.8/site-packages/sqlalchemy/pool/base.py", line 388, in __init__
    self.__connect()
  File "/home/airflow/.local/lib/python3.8/site-packages/sqlalchemy/pool/base.py", line 691, in __connect
    pool.logger.debug("Error on connect(): %s", e)
  File "/home/airflow/.local/lib/python3.8/site-packages/sqlalchemy/util/langhelpers.py", line 70, in __exit__
    compat.raise_(
  File "/home/airflow/.local/lib/python3.8/site-packages/sqlalchemy/util/compat.py", line 211, in raise_
    raise exception
  File "/home/airflow/.local/lib/python3.8/site-packages/sqlalchemy/pool/base.py", line 686, in __connect
    self.dbapi_connection = connection = pool._invoke_creator(self)
  File "/home/airflow/.local/lib/python3.8/site-packages/sqlalchemy/engine/create.py", line 574, in connect
    return dialect.connect(*cargs, **cparams)
  File "/home/airflow/.local/lib/python3.8/site-packages/sqlalchemy/engine/default.py", line 598, in connect
    return self.dbapi.connect(*cargs, **cparams)
  File "/home/airflow/.local/lib/python3.8/site-packages/psycopg2/__init__.py", line 122, in connect
    conn = _connect(dsn, connection_factory=connection_factory, **kwasync)
sqlalchemy.exc.OperationalError: (psycopg2.OperationalError) could not translate host name "postgres" to address: Temporary failure in name resolution

(Background on this error at: https://sqlalche.me/e/14/e3q8)
[2023-11-11T07:15:38.848+0000] {job.py:219} ERROR - Job heartbeat got an exception
Traceback (most recent call last):
  File "/home/airflow/.local/lib/python3.8/site-packages/sqlalchemy/engine/base.py", line 3371, in _wrap_pool_connect
    return fn()
  File "/home/airflow/.local/lib/python3.8/site-packages/sqlalchemy/pool/base.py", line 327, in connect
    return _ConnectionFairy._checkout(self)
  File "/home/airflow/.local/lib/python3.8/site-packages/sqlalchemy/pool/base.py", line 894, in _checkout
    fairy = _ConnectionRecord.checkout(pool)
  File "/home/airflow/.local/lib/python3.8/site-packages/sqlalchemy/pool/base.py", line 493, in checkout
    rec = pool._do_get()
  File "/home/airflow/.local/lib/python3.8/site-packages/sqlalchemy/pool/impl.py", line 256, in _do_get
    return self._create_connection()
  File "/home/airflow/.local/lib/python3.8/site-packages/sqlalchemy/pool/base.py", line 273, in _create_connection
    return _ConnectionRecord(self)
  File "/home/airflow/.local/lib/python3.8/site-packages/sqlalchemy/pool/base.py", line 388, in __init__
    self.__connect()
  File "/home/airflow/.local/lib/python3.8/site-packages/sqlalchemy/pool/base.py", line 691, in __connect
    pool.logger.debug("Error on connect(): %s", e)
  File "/home/airflow/.local/lib/python3.8/site-packages/sqlalchemy/util/langhelpers.py", line 70, in __exit__
    compat.raise_(
  File "/home/airflow/.local/lib/python3.8/site-packages/sqlalchemy/util/compat.py", line 211, in raise_
    raise exception
  File "/home/airflow/.local/lib/python3.8/site-packages/sqlalchemy/pool/base.py", line 686, in __connect
    self.dbapi_connection = connection = pool._invoke_creator(self)
  File "/home/airflow/.local/lib/python3.8/site-packages/sqlalchemy/engine/create.py", line 574, in connect
    return dialect.connect(*cargs, **cparams)
  File "/home/airflow/.local/lib/python3.8/site-packages/sqlalchemy/engine/default.py", line 598, in connect
    return self.dbapi.connect(*cargs, **cparams)
  File "/home/airflow/.local/lib/python3.8/site-packages/psycopg2/__init__.py", line 122, in connect
    conn = _connect(dsn, connection_factory=connection_factory, **kwasync)
psycopg2.OperationalError: could not translate host name "postgres" to address: Temporary failure in name resolution


The above exception was the direct cause of the following exception:

Traceback (most recent call last):
  File "/home/airflow/.local/lib/python3.8/site-packages/airflow/jobs/job.py", line 190, in heartbeat
    session.merge(self)
  File "/home/airflow/.local/lib/python3.8/site-packages/sqlalchemy/orm/session.py", line 3056, in merge
    return self._merge(
  File "/home/airflow/.local/lib/python3.8/site-packages/sqlalchemy/orm/session.py", line 3136, in _merge
    merged = self.get(
  File "/home/airflow/.local/lib/python3.8/site-packages/sqlalchemy/orm/session.py", line 2853, in get
    return self._get_impl(
  File "/home/airflow/.local/lib/python3.8/site-packages/sqlalchemy/orm/session.py", line 2975, in _get_impl
    return db_load_fn(
  File "/home/airflow/.local/lib/python3.8/site-packages/sqlalchemy/orm/loading.py", line 530, in load_on_pk_identity
    session.execute(
  File "/home/airflow/.local/lib/python3.8/site-packages/sqlalchemy/orm/session.py", line 1716, in execute
    conn = self._connection_for_bind(bind)
  File "/home/airflow/.local/lib/python3.8/site-packages/sqlalchemy/orm/session.py", line 1555, in _connection_for_bind
    return self._transaction._connection_for_bind(
  File "/home/airflow/.local/lib/python3.8/site-packages/sqlalchemy/orm/session.py", line 750, in _connection_for_bind
    conn = bind.connect()
  File "/home/airflow/.local/lib/python3.8/site-packages/sqlalchemy/future/engine.py", line 406, in connect
    return super(Engine, self).connect()
  File "/home/airflow/.local/lib/python3.8/site-packages/sqlalchemy/engine/base.py", line 3325, in connect
    return self._connection_cls(self, close_with_result=close_with_result)
  File "/home/airflow/.local/lib/python3.8/site-packages/sqlalchemy/engine/base.py", line 96, in __init__
    else engine.raw_connection()
  File "/home/airflow/.local/lib/python3.8/site-packages/sqlalchemy/engine/base.py", line 3404, in raw_connection
    return self._wrap_pool_connect(self.pool.connect, _connection)
  File "/home/airflow/.local/lib/python3.8/site-packages/sqlalchemy/engine/base.py", line 3374, in _wrap_pool_connect
    Connection._handle_dbapi_exception_noconnection(
  File "/home/airflow/.local/lib/python3.8/site-packages/sqlalchemy/engine/base.py", line 2208, in _handle_dbapi_exception_noconnection
    util.raise_(
  File "/home/airflow/.local/lib/python3.8/site-packages/sqlalchemy/util/compat.py", line 211, in raise_
    raise exception
  File "/home/airflow/.local/lib/python3.8/site-packages/sqlalchemy/engine/base.py", line 3371, in _wrap_pool_connect
    return fn()
  File "/home/airflow/.local/lib/python3.8/site-packages/sqlalchemy/pool/base.py", line 327, in connect
    return _ConnectionFairy._checkout(self)
  File "/home/airflow/.local/lib/python3.8/site-packages/sqlalchemy/pool/base.py", line 894, in _checkout
    fairy = _ConnectionRecord.checkout(pool)
  File "/home/airflow/.local/lib/python3.8/site-packages/sqlalchemy/pool/base.py", line 493, in checkout
    rec = pool._do_get()
  File "/home/airflow/.local/lib/python3.8/site-packages/sqlalchemy/pool/impl.py", line 256, in _do_get
    return self._create_connection()
  File "/home/airflow/.local/lib/python3.8/site-packages/sqlalchemy/pool/base.py", line 273, in _create_connection
    return _ConnectionRecord(self)
  File "/home/airflow/.local/lib/python3.8/site-packages/sqlalchemy/pool/base.py", line 388, in __init__
    self.__connect()
  File "/home/airflow/.local/lib/python3.8/site-packages/sqlalchemy/pool/base.py", line 691, in __connect
    pool.logger.debug("Error on connect(): %s", e)
  File "/home/airflow/.local/lib/python3.8/site-packages/sqlalchemy/util/langhelpers.py", line 70, in __exit__
    compat.raise_(
  File "/home/airflow/.local/lib/python3.8/site-packages/sqlalchemy/util/compat.py", line 211, in raise_
    raise exception
  File "/home/airflow/.local/lib/python3.8/site-packages/sqlalchemy/pool/base.py", line 686, in __connect
    self.dbapi_connection = connection = pool._invoke_creator(self)
  File "/home/airflow/.local/lib/python3.8/site-packages/sqlalchemy/engine/create.py", line 574, in connect
    return dialect.connect(*cargs, **cparams)
  File "/home/airflow/.local/lib/python3.8/site-packages/sqlalchemy/engine/default.py", line 598, in connect
    return self.dbapi.connect(*cargs, **cparams)
  File "/home/airflow/.local/lib/python3.8/site-packages/psycopg2/__init__.py", line 122, in connect
    conn = _connect(dsn, connection_factory=connection_factory, **kwasync)
sqlalchemy.exc.OperationalError: (psycopg2.OperationalError) could not translate host name "postgres" to address: Temporary failure in name resolution

(Background on this error at: https://sqlalche.me/e/14/e3q8)
[2023-11-11T07:15:54.979+0000] {job.py:219} ERROR - Job heartbeat got an exception
Traceback (most recent call last):
  File "/home/airflow/.local/lib/python3.8/site-packages/sqlalchemy/engine/base.py", line 3371, in _wrap_pool_connect
    return fn()
  File "/home/airflow/.local/lib/python3.8/site-packages/sqlalchemy/pool/base.py", line 327, in connect
    return _ConnectionFairy._checkout(self)
  File "/home/airflow/.local/lib/python3.8/site-packages/sqlalchemy/pool/base.py", line 894, in _checkout
    fairy = _ConnectionRecord.checkout(pool)
  File "/home/airflow/.local/lib/python3.8/site-packages/sqlalchemy/pool/base.py", line 493, in checkout
    rec = pool._do_get()
  File "/home/airflow/.local/lib/python3.8/site-packages/sqlalchemy/pool/impl.py", line 256, in _do_get
    return self._create_connection()
  File "/home/airflow/.local/lib/python3.8/site-packages/sqlalchemy/pool/base.py", line 273, in _create_connection
    return _ConnectionRecord(self)
  File "/home/airflow/.local/lib/python3.8/site-packages/sqlalchemy/pool/base.py", line 388, in __init__
    self.__connect()
  File "/home/airflow/.local/lib/python3.8/site-packages/sqlalchemy/pool/base.py", line 691, in __connect
    pool.logger.debug("Error on connect(): %s", e)
  File "/home/airflow/.local/lib/python3.8/site-packages/sqlalchemy/util/langhelpers.py", line 70, in __exit__
    compat.raise_(
  File "/home/airflow/.local/lib/python3.8/site-packages/sqlalchemy/util/compat.py", line 211, in raise_
    raise exception
  File "/home/airflow/.local/lib/python3.8/site-packages/sqlalchemy/pool/base.py", line 686, in __connect
    self.dbapi_connection = connection = pool._invoke_creator(self)
  File "/home/airflow/.local/lib/python3.8/site-packages/sqlalchemy/engine/create.py", line 574, in connect
    return dialect.connect(*cargs, **cparams)
  File "/home/airflow/.local/lib/python3.8/site-packages/sqlalchemy/engine/default.py", line 598, in connect
    return self.dbapi.connect(*cargs, **cparams)
  File "/home/airflow/.local/lib/python3.8/site-packages/psycopg2/__init__.py", line 122, in connect
    conn = _connect(dsn, connection_factory=connection_factory, **kwasync)
psycopg2.OperationalError: could not translate host name "postgres" to address: Temporary failure in name resolution


The above exception was the direct cause of the following exception:

Traceback (most recent call last):
  File "/home/airflow/.local/lib/python3.8/site-packages/airflow/jobs/job.py", line 190, in heartbeat
    session.merge(self)
  File "/home/airflow/.local/lib/python3.8/site-packages/sqlalchemy/orm/session.py", line 3056, in merge
    return self._merge(
  File "/home/airflow/.local/lib/python3.8/site-packages/sqlalchemy/orm/session.py", line 3136, in _merge
    merged = self.get(
  File "/home/airflow/.local/lib/python3.8/site-packages/sqlalchemy/orm/session.py", line 2853, in get
    return self._get_impl(
  File "/home/airflow/.local/lib/python3.8/site-packages/sqlalchemy/orm/session.py", line 2975, in _get_impl
    return db_load_fn(
  File "/home/airflow/.local/lib/python3.8/site-packages/sqlalchemy/orm/loading.py", line 530, in load_on_pk_identity
    session.execute(
  File "/home/airflow/.local/lib/python3.8/site-packages/sqlalchemy/orm/session.py", line 1716, in execute
    conn = self._connection_for_bind(bind)
  File "/home/airflow/.local/lib/python3.8/site-packages/sqlalchemy/orm/session.py", line 1555, in _connection_for_bind
    return self._transaction._connection_for_bind(
  File "/home/airflow/.local/lib/python3.8/site-packages/sqlalchemy/orm/session.py", line 750, in _connection_for_bind
    conn = bind.connect()
  File "/home/airflow/.local/lib/python3.8/site-packages/sqlalchemy/future/engine.py", line 406, in connect
    return super(Engine, self).connect()
  File "/home/airflow/.local/lib/python3.8/site-packages/sqlalchemy/engine/base.py", line 3325, in connect
    return self._connection_cls(self, close_with_result=close_with_result)
  File "/home/airflow/.local/lib/python3.8/site-packages/sqlalchemy/engine/base.py", line 96, in __init__
    else engine.raw_connection()
  File "/home/airflow/.local/lib/python3.8/site-packages/sqlalchemy/engine/base.py", line 3404, in raw_connection
    return self._wrap_pool_connect(self.pool.connect, _connection)
  File "/home/airflow/.local/lib/python3.8/site-packages/sqlalchemy/engine/base.py", line 3374, in _wrap_pool_connect
    Connection._handle_dbapi_exception_noconnection(
  File "/home/airflow/.local/lib/python3.8/site-packages/sqlalchemy/engine/base.py", line 2208, in _handle_dbapi_exception_noconnection
    util.raise_(
  File "/home/airflow/.local/lib/python3.8/site-packages/sqlalchemy/util/compat.py", line 211, in raise_
    raise exception
  File "/home/airflow/.local/lib/python3.8/site-packages/sqlalchemy/engine/base.py", line 3371, in _wrap_pool_connect
    return fn()
  File "/home/airflow/.local/lib/python3.8/site-packages/sqlalchemy/pool/base.py", line 327, in connect
    return _ConnectionFairy._checkout(self)
  File "/home/airflow/.local/lib/python3.8/site-packages/sqlalchemy/pool/base.py", line 894, in _checkout
    fairy = _ConnectionRecord.checkout(pool)
  File "/home/airflow/.local/lib/python3.8/site-packages/sqlalchemy/pool/base.py", line 493, in checkout
    rec = pool._do_get()
  File "/home/airflow/.local/lib/python3.8/site-packages/sqlalchemy/pool/impl.py", line 256, in _do_get
    return self._create_connection()
  File "/home/airflow/.local/lib/python3.8/site-packages/sqlalchemy/pool/base.py", line 273, in _create_connection
    return _ConnectionRecord(self)
  File "/home/airflow/.local/lib/python3.8/site-packages/sqlalchemy/pool/base.py", line 388, in __init__
    self.__connect()
  File "/home/airflow/.local/lib/python3.8/site-packages/sqlalchemy/pool/base.py", line 691, in __connect
    pool.logger.debug("Error on connect(): %s", e)
  File "/home/airflow/.local/lib/python3.8/site-packages/sqlalchemy/util/langhelpers.py", line 70, in __exit__
    compat.raise_(
  File "/home/airflow/.local/lib/python3.8/site-packages/sqlalchemy/util/compat.py", line 211, in raise_
    raise exception
  File "/home/airflow/.local/lib/python3.8/site-packages/sqlalchemy/pool/base.py", line 686, in __connect
    self.dbapi_connection = connection = pool._invoke_creator(self)
  File "/home/airflow/.local/lib/python3.8/site-packages/sqlalchemy/engine/create.py", line 574, in connect
    return dialect.connect(*cargs, **cparams)
  File "/home/airflow/.local/lib/python3.8/site-packages/sqlalchemy/engine/default.py", line 598, in connect
    return self.dbapi.connect(*cargs, **cparams)
  File "/home/airflow/.local/lib/python3.8/site-packages/psycopg2/__init__.py", line 122, in connect
    conn = _connect(dsn, connection_factory=connection_factory, **kwasync)
sqlalchemy.exc.OperationalError: (psycopg2.OperationalError) could not translate host name "postgres" to address: Temporary failure in name resolution

(Background on this error at: https://sqlalche.me/e/14/e3q8)
[2023-11-11T07:16:05.228+0000] {local_task_job_runner.py:115} ERROR - Received SIGTERM. Terminating subprocesses
[2023-11-11T07:16:05.698+0000] {process_utils.py:131} INFO - Sending 15 to group 254. PIDs of all processes in the group: [254]
[2023-11-11T07:16:05.764+0000] {process_utils.py:86} INFO - Sending the signal 15 to group 254
[2023-11-11T07:16:06.223+0000] {taskinstance.py:1632} ERROR - Received SIGTERM. Terminating subprocesses.
[2023-11-11T07:16:07.479+0000] {taskinstance.py:1937} ERROR - Task failed with exception
Traceback (most recent call last):
  File "/home/airflow/.local/lib/python3.8/site-packages/airflow/operators/python.py", line 192, in execute
    return_value = self.execute_callable()
  File "/home/airflow/.local/lib/python3.8/site-packages/airflow/operators/python.py", line 209, in execute_callable
    return self.python_callable(*self.op_args, **self.op_kwargs)
  File "/opt/airflow/dags/src/datapreprocessing.py", line 30, in split_dataset
    X_test.to_csv(os.path.join(os.path.dirname(__file__), "../data/X_test.csv"), index=False)
  File "/home/airflow/.local/lib/python3.8/site-packages/pandas/core/generic.py", line 3772, in to_csv
    return DataFrameRenderer(formatter).to_csv(
  File "/home/airflow/.local/lib/python3.8/site-packages/pandas/io/formats/format.py", line 1186, in to_csv
    csv_formatter.save()
  File "/home/airflow/.local/lib/python3.8/site-packages/pandas/io/formats/csvs.py", line 259, in save
    self._save()
  File "/home/airflow/.local/lib/python3.8/site-packages/pandas/io/formats/csvs.py", line 264, in _save
    self._save_body()
  File "/home/airflow/.local/lib/python3.8/site-packages/pandas/io/formats/csvs.py", line 302, in _save_body
    self._save_chunk(start_i, end_i)
  File "/home/airflow/.local/lib/python3.8/site-packages/airflow/models/taskinstance.py", line 1634, in signal_handler
    raise AirflowException("Task received SIGTERM signal")
airflow.exceptions.AirflowException: Task received SIGTERM signal
[2023-11-11T07:16:07.870+0000] {taskinstance.py:1400} INFO - Marking task as UP_FOR_RETRY. dag_id=preprocessing_v1, task_id=split_task, execution_date=20231111T071432, start_date=20231111T071435, end_date=20231111T071607
[2023-11-11T07:16:08.373+0000] {standard_task_runner.py:104} ERROR - Failed to execute job 3 for task split_task (Task received SIGTERM signal; 254)
[2023-11-11T07:16:08.663+0000] {process_utils.py:79} INFO - Process psutil.Process(pid=254, status='terminated', exitcode=1, started='07:14:34') (254) terminated with exit code 1
[2023-11-11T07:16:08.707+0000] {local_task_job_runner.py:228} INFO - Task exited with return code 143
[2023-11-11T07:16:10.076+0000] {taskinstance.py:2778} INFO - 0 downstream tasks scheduled from follow-on schedule check
