[2023-11-11T03:25:19.670+0000] {taskinstance.py:1159} INFO - Dependencies all met for dep_context=non-requeueable deps ti=<TaskInstance: preprocessing_v1.split_task scheduled__2023-11-10T00:00:00+00:00 [queued]>
[2023-11-11T03:25:19.677+0000] {taskinstance.py:1159} INFO - Dependencies all met for dep_context=requeueable deps ti=<TaskInstance: preprocessing_v1.split_task scheduled__2023-11-10T00:00:00+00:00 [queued]>
[2023-11-11T03:25:19.677+0000] {taskinstance.py:1361} INFO - Starting attempt 1 of 6
[2023-11-11T03:25:19.686+0000] {taskinstance.py:1382} INFO - Executing <Task(PythonOperator): split_task> on 2023-11-10 00:00:00+00:00
[2023-11-11T03:25:19.691+0000] {standard_task_runner.py:57} INFO - Started process 239 to run task
[2023-11-11T03:25:19.696+0000] {standard_task_runner.py:84} INFO - Running: ['***', 'tasks', 'run', 'preprocessing_v1', 'split_task', 'scheduled__2023-11-10T00:00:00+00:00', '--job-id', '8', '--raw', '--subdir', 'DAGS_FOLDER/***_code.py', '--cfg-path', '/tmp/tmpqjctflr2']
[2023-11-11T03:25:19.700+0000] {standard_task_runner.py:85} INFO - Job 8: Subtask split_task
[2023-11-11T03:25:19.742+0000] {task_command.py:416} INFO - Running <TaskInstance: preprocessing_v1.split_task scheduled__2023-11-10T00:00:00+00:00 [running]> on host d2c761eebca3
[2023-11-11T03:25:19.822+0000] {taskinstance.py:1662} INFO - Exporting env vars: AIRFLOW_CTX_DAG_OWNER='Team 3' AIRFLOW_CTX_DAG_ID='preprocessing_v1' AIRFLOW_CTX_TASK_ID='split_task' AIRFLOW_CTX_EXECUTION_DATE='2023-11-10T00:00:00+00:00' AIRFLOW_CTX_TRY_NUMBER='1' AIRFLOW_CTX_DAG_RUN_ID='scheduled__2023-11-10T00:00:00+00:00'
[2023-11-11T03:25:21.667+0000] {python.py:194} INFO - Done. Returned value was: 1
[2023-11-11T03:25:21.686+0000] {taskinstance.py:1400} INFO - Marking task as SUCCESS. dag_id=preprocessing_v1, task_id=split_task, execution_date=20231110T000000, start_date=20231111T032519, end_date=20231111T032521
[2023-11-11T03:25:21.737+0000] {local_task_job_runner.py:228} INFO - Task exited with return code 0
[2023-11-11T03:25:21.755+0000] {taskinstance.py:2778} INFO - 1 downstream tasks scheduled from follow-on schedule check
[2023-11-11T03:29:36.889+0000] {taskinstance.py:1159} INFO - Dependencies all met for dep_context=non-requeueable deps ti=<TaskInstance: preprocessing_v1.split_task scheduled__2023-11-10T00:00:00+00:00 [queued]>
[2023-11-11T03:29:36.895+0000] {taskinstance.py:1159} INFO - Dependencies all met for dep_context=requeueable deps ti=<TaskInstance: preprocessing_v1.split_task scheduled__2023-11-10T00:00:00+00:00 [queued]>
[2023-11-11T03:29:36.896+0000] {taskinstance.py:1361} INFO - Starting attempt 1 of 6
[2023-11-11T03:29:36.904+0000] {taskinstance.py:1382} INFO - Executing <Task(PythonOperator): split_task> on 2023-11-10 00:00:00+00:00
[2023-11-11T03:29:36.912+0000] {standard_task_runner.py:57} INFO - Started process 254 to run task
[2023-11-11T03:29:36.916+0000] {standard_task_runner.py:84} INFO - Running: ['***', 'tasks', 'run', 'preprocessing_v1', 'split_task', 'scheduled__2023-11-10T00:00:00+00:00', '--job-id', '6', '--raw', '--subdir', 'DAGS_FOLDER/***_code.py', '--cfg-path', '/tmp/tmpjg7faw16']
[2023-11-11T03:29:36.920+0000] {standard_task_runner.py:85} INFO - Job 6: Subtask split_task
[2023-11-11T03:29:36.969+0000] {task_command.py:416} INFO - Running <TaskInstance: preprocessing_v1.split_task scheduled__2023-11-10T00:00:00+00:00 [running]> on host 9c8a8ec1a519
[2023-11-11T03:29:37.037+0000] {taskinstance.py:1662} INFO - Exporting env vars: AIRFLOW_CTX_DAG_OWNER='Team 3' AIRFLOW_CTX_DAG_ID='preprocessing_v1' AIRFLOW_CTX_TASK_ID='split_task' AIRFLOW_CTX_EXECUTION_DATE='2023-11-10T00:00:00+00:00' AIRFLOW_CTX_TRY_NUMBER='1' AIRFLOW_CTX_DAG_RUN_ID='scheduled__2023-11-10T00:00:00+00:00'
[2023-11-11T03:29:38.848+0000] {python.py:194} INFO - Done. Returned value was: 1
[2023-11-11T03:29:38.863+0000] {taskinstance.py:1400} INFO - Marking task as SUCCESS. dag_id=preprocessing_v1, task_id=split_task, execution_date=20231110T000000, start_date=20231111T032936, end_date=20231111T032938
[2023-11-11T03:29:38.887+0000] {local_task_job_runner.py:228} INFO - Task exited with return code 0
[2023-11-11T03:29:38.911+0000] {taskinstance.py:2778} INFO - 0 downstream tasks scheduled from follow-on schedule check
[2023-11-11T03:41:55.285+0000] {taskinstance.py:1159} INFO - Dependencies all met for dep_context=non-requeueable deps ti=<TaskInstance: preprocessing_v1.split_task scheduled__2023-11-10T00:00:00+00:00 [queued]>
[2023-11-11T03:41:55.292+0000] {taskinstance.py:1159} INFO - Dependencies all met for dep_context=requeueable deps ti=<TaskInstance: preprocessing_v1.split_task scheduled__2023-11-10T00:00:00+00:00 [queued]>
[2023-11-11T03:41:55.292+0000] {taskinstance.py:1361} INFO - Starting attempt 1 of 6
[2023-11-11T03:41:55.300+0000] {taskinstance.py:1382} INFO - Executing <Task(PythonOperator): split_task> on 2023-11-10 00:00:00+00:00
[2023-11-11T03:41:55.310+0000] {standard_task_runner.py:57} INFO - Started process 232 to run task
[2023-11-11T03:41:55.327+0000] {standard_task_runner.py:84} INFO - Running: ['***', 'tasks', 'run', 'preprocessing_v1', 'split_task', 'scheduled__2023-11-10T00:00:00+00:00', '--job-id', '5', '--raw', '--subdir', 'DAGS_FOLDER/***_code.py', '--cfg-path', '/tmp/tmpwx1p2fi3']
[2023-11-11T03:41:55.331+0000] {standard_task_runner.py:85} INFO - Job 5: Subtask split_task
[2023-11-11T03:41:55.404+0000] {task_command.py:416} INFO - Running <TaskInstance: preprocessing_v1.split_task scheduled__2023-11-10T00:00:00+00:00 [running]> on host 27df91229c7e
[2023-11-11T03:41:55.458+0000] {taskinstance.py:1662} INFO - Exporting env vars: AIRFLOW_CTX_DAG_OWNER='Team 3' AIRFLOW_CTX_DAG_ID='preprocessing_v1' AIRFLOW_CTX_TASK_ID='split_task' AIRFLOW_CTX_EXECUTION_DATE='2023-11-10T00:00:00+00:00' AIRFLOW_CTX_TRY_NUMBER='1' AIRFLOW_CTX_DAG_RUN_ID='scheduled__2023-11-10T00:00:00+00:00'
[2023-11-11T03:41:55.460+0000] {datapreprocessing.py:40} INFO - Splitting dataset...
[2023-11-11T03:41:57.417+0000] {datapreprocessing.py:52} INFO - Dataset split.
[2023-11-11T03:41:57.420+0000] {python.py:194} INFO - Done. Returned value was: 1
[2023-11-11T03:41:57.433+0000] {taskinstance.py:1400} INFO - Marking task as SUCCESS. dag_id=preprocessing_v1, task_id=split_task, execution_date=20231110T000000, start_date=20231111T034155, end_date=20231111T034157
[2023-11-11T03:41:57.460+0000] {local_task_job_runner.py:228} INFO - Task exited with return code 0
[2023-11-11T03:41:57.478+0000] {taskinstance.py:2778} INFO - 1 downstream tasks scheduled from follow-on schedule check
[2023-11-11T04:44:18.637+0000] {taskinstance.py:1159} INFO - Dependencies all met for dep_context=non-requeueable deps ti=<TaskInstance: preprocessing_v1.split_task scheduled__2023-11-10T00:00:00+00:00 [queued]>
[2023-11-11T04:44:18.642+0000] {taskinstance.py:1159} INFO - Dependencies all met for dep_context=requeueable deps ti=<TaskInstance: preprocessing_v1.split_task scheduled__2023-11-10T00:00:00+00:00 [queued]>
[2023-11-11T04:44:18.643+0000] {taskinstance.py:1361} INFO - Starting attempt 1 of 6
[2023-11-11T04:44:18.651+0000] {taskinstance.py:1382} INFO - Executing <Task(PythonOperator): split_task> on 2023-11-10 00:00:00+00:00
[2023-11-11T04:44:18.659+0000] {standard_task_runner.py:57} INFO - Started process 231 to run task
[2023-11-11T04:44:18.664+0000] {standard_task_runner.py:84} INFO - Running: ['***', 'tasks', 'run', 'preprocessing_v1', 'split_task', 'scheduled__2023-11-10T00:00:00+00:00', '--job-id', '5', '--raw', '--subdir', 'DAGS_FOLDER/***_code.py', '--cfg-path', '/tmp/tmp9uya2hll']
[2023-11-11T04:44:18.668+0000] {standard_task_runner.py:85} INFO - Job 5: Subtask split_task
[2023-11-11T04:44:18.725+0000] {task_command.py:416} INFO - Running <TaskInstance: preprocessing_v1.split_task scheduled__2023-11-10T00:00:00+00:00 [running]> on host bb20688940fc
[2023-11-11T04:44:18.785+0000] {taskinstance.py:1662} INFO - Exporting env vars: AIRFLOW_CTX_DAG_OWNER='Team 3' AIRFLOW_CTX_DAG_ID='preprocessing_v1' AIRFLOW_CTX_TASK_ID='split_task' AIRFLOW_CTX_EXECUTION_DATE='2023-11-10T00:00:00+00:00' AIRFLOW_CTX_TRY_NUMBER='1' AIRFLOW_CTX_DAG_RUN_ID='scheduled__2023-11-10T00:00:00+00:00'
[2023-11-11T04:44:18.786+0000] {datapreprocessing.py:39} INFO - Splitting dataset...
[2023-11-11T04:44:21.015+0000] {datapreprocessing.py:51} INFO - Dataset split.
[2023-11-11T04:44:21.018+0000] {python.py:194} INFO - Done. Returned value was: 1
[2023-11-11T04:44:21.041+0000] {taskinstance.py:1400} INFO - Marking task as SUCCESS. dag_id=preprocessing_v1, task_id=split_task, execution_date=20231110T000000, start_date=20231111T044418, end_date=20231111T044421
[2023-11-11T04:44:21.075+0000] {local_task_job_runner.py:228} INFO - Task exited with return code 0
[2023-11-11T04:44:21.104+0000] {taskinstance.py:2778} INFO - 1 downstream tasks scheduled from follow-on schedule check
[2023-11-11T07:08:25.504+0000] {taskinstance.py:1159} INFO - Dependencies all met for dep_context=non-requeueable deps ti=<TaskInstance: preprocessing_v1.split_task scheduled__2023-11-10T00:00:00+00:00 [queued]>
[2023-11-11T07:08:25.537+0000] {taskinstance.py:1159} INFO - Dependencies all met for dep_context=requeueable deps ti=<TaskInstance: preprocessing_v1.split_task scheduled__2023-11-10T00:00:00+00:00 [queued]>
[2023-11-11T07:08:25.538+0000] {taskinstance.py:1361} INFO - Starting attempt 1 of 6
[2023-11-11T07:08:25.562+0000] {taskinstance.py:1382} INFO - Executing <Task(PythonOperator): split_task> on 2023-11-10 00:00:00+00:00
[2023-11-11T07:08:25.590+0000] {standard_task_runner.py:57} INFO - Started process 256 to run task
[2023-11-11T07:08:25.611+0000] {standard_task_runner.py:84} INFO - Running: ['***', 'tasks', 'run', 'preprocessing_v1', 'split_task', 'scheduled__2023-11-10T00:00:00+00:00', '--job-id', '6', '--raw', '--subdir', 'DAGS_FOLDER/***_code.py', '--cfg-path', '/tmp/tmpzaakkb_v']
[2023-11-11T07:08:25.626+0000] {standard_task_runner.py:85} INFO - Job 6: Subtask split_task
[2023-11-11T07:08:25.792+0000] {task_command.py:416} INFO - Running <TaskInstance: preprocessing_v1.split_task scheduled__2023-11-10T00:00:00+00:00 [running]> on host bce5ad10b059
[2023-11-11T07:08:26.026+0000] {taskinstance.py:1662} INFO - Exporting env vars: AIRFLOW_CTX_DAG_OWNER='Team 3' AIRFLOW_CTX_DAG_ID='preprocessing_v1' AIRFLOW_CTX_TASK_ID='split_task' AIRFLOW_CTX_EXECUTION_DATE='2023-11-10T00:00:00+00:00' AIRFLOW_CTX_TRY_NUMBER='1' AIRFLOW_CTX_DAG_RUN_ID='scheduled__2023-11-10T00:00:00+00:00'
[2023-11-11T07:08:28.785+0000] {python.py:194} INFO - Done. Returned value was: 1
[2023-11-11T07:08:28.992+0000] {taskinstance.py:1400} INFO - Marking task as SUCCESS. dag_id=preprocessing_v1, task_id=split_task, execution_date=20231110T000000, start_date=20231111T070825, end_date=20231111T070828
[2023-11-11T07:08:29.090+0000] {local_task_job_runner.py:228} INFO - Task exited with return code 0
[2023-11-11T07:08:29.295+0000] {taskinstance.py:2778} INFO - 1 downstream tasks scheduled from follow-on schedule check
[2023-11-11T07:14:35.471+0000] {taskinstance.py:1159} INFO - Dependencies all met for dep_context=non-requeueable deps ti=<TaskInstance: preprocessing_v1.split_task scheduled__2023-11-10T00:00:00+00:00 [queued]>
[2023-11-11T07:14:35.486+0000] {taskinstance.py:1159} INFO - Dependencies all met for dep_context=requeueable deps ti=<TaskInstance: preprocessing_v1.split_task scheduled__2023-11-10T00:00:00+00:00 [queued]>
[2023-11-11T07:14:35.486+0000] {taskinstance.py:1361} INFO - Starting attempt 1 of 6
[2023-11-11T07:14:35.503+0000] {taskinstance.py:1382} INFO - Executing <Task(PythonOperator): split_task> on 2023-11-10 00:00:00+00:00
[2023-11-11T07:14:35.520+0000] {standard_task_runner.py:57} INFO - Started process 251 to run task
[2023-11-11T07:14:35.529+0000] {standard_task_runner.py:84} INFO - Running: ['***', 'tasks', 'run', 'preprocessing_v1', 'split_task', 'scheduled__2023-11-10T00:00:00+00:00', '--job-id', '4', '--raw', '--subdir', 'DAGS_FOLDER/***_code.py', '--cfg-path', '/tmp/tmpxkxs7gnh']
[2023-11-11T07:14:35.554+0000] {standard_task_runner.py:85} INFO - Job 4: Subtask split_task
[2023-11-11T07:14:35.806+0000] {task_command.py:416} INFO - Running <TaskInstance: preprocessing_v1.split_task scheduled__2023-11-10T00:00:00+00:00 [running]> on host ab7bd6d8471a
[2023-11-11T07:14:36.178+0000] {taskinstance.py:1662} INFO - Exporting env vars: AIRFLOW_CTX_DAG_OWNER='Team 3' AIRFLOW_CTX_DAG_ID='preprocessing_v1' AIRFLOW_CTX_TASK_ID='split_task' AIRFLOW_CTX_EXECUTION_DATE='2023-11-10T00:00:00+00:00' AIRFLOW_CTX_TRY_NUMBER='1' AIRFLOW_CTX_DAG_RUN_ID='scheduled__2023-11-10T00:00:00+00:00'
[2023-11-11T07:14:57.737+0000] {job.py:219} ERROR - Job heartbeat got an exception
Traceback (most recent call last):
  File "/home/airflow/.local/lib/python3.8/site-packages/sqlalchemy/engine/base.py", line 3371, in _wrap_pool_connect
    return fn()
  File "/home/airflow/.local/lib/python3.8/site-packages/sqlalchemy/pool/base.py", line 327, in connect
    return _ConnectionFairy._checkout(self)
  File "/home/airflow/.local/lib/python3.8/site-packages/sqlalchemy/pool/base.py", line 894, in _checkout
    fairy = _ConnectionRecord.checkout(pool)
  File "/home/airflow/.local/lib/python3.8/site-packages/sqlalchemy/pool/base.py", line 493, in checkout
    rec = pool._do_get()
  File "/home/airflow/.local/lib/python3.8/site-packages/sqlalchemy/pool/impl.py", line 256, in _do_get
    return self._create_connection()
  File "/home/airflow/.local/lib/python3.8/site-packages/sqlalchemy/pool/base.py", line 273, in _create_connection
    return _ConnectionRecord(self)
  File "/home/airflow/.local/lib/python3.8/site-packages/sqlalchemy/pool/base.py", line 388, in __init__
    self.__connect()
  File "/home/airflow/.local/lib/python3.8/site-packages/sqlalchemy/pool/base.py", line 691, in __connect
    pool.logger.debug("Error on connect(): %s", e)
  File "/home/airflow/.local/lib/python3.8/site-packages/sqlalchemy/util/langhelpers.py", line 70, in __exit__
    compat.raise_(
  File "/home/airflow/.local/lib/python3.8/site-packages/sqlalchemy/util/compat.py", line 211, in raise_
    raise exception
  File "/home/airflow/.local/lib/python3.8/site-packages/sqlalchemy/pool/base.py", line 686, in __connect
    self.dbapi_connection = connection = pool._invoke_creator(self)
  File "/home/airflow/.local/lib/python3.8/site-packages/sqlalchemy/engine/create.py", line 574, in connect
    return dialect.connect(*cargs, **cparams)
  File "/home/airflow/.local/lib/python3.8/site-packages/sqlalchemy/engine/default.py", line 598, in connect
    return self.dbapi.connect(*cargs, **cparams)
  File "/home/airflow/.local/lib/python3.8/site-packages/psycopg2/__init__.py", line 122, in connect
    conn = _connect(dsn, connection_factory=connection_factory, **kwasync)
psycopg2.OperationalError: could not translate host name "postgres" to address: Temporary failure in name resolution


The above exception was the direct cause of the following exception:

Traceback (most recent call last):
  File "/home/airflow/.local/lib/python3.8/site-packages/airflow/jobs/job.py", line 190, in heartbeat
    session.merge(self)
  File "/home/airflow/.local/lib/python3.8/site-packages/sqlalchemy/orm/session.py", line 3056, in merge
    return self._merge(
  File "/home/airflow/.local/lib/python3.8/site-packages/sqlalchemy/orm/session.py", line 3136, in _merge
    merged = self.get(
  File "/home/airflow/.local/lib/python3.8/site-packages/sqlalchemy/orm/session.py", line 2853, in get
    return self._get_impl(
  File "/home/airflow/.local/lib/python3.8/site-packages/sqlalchemy/orm/session.py", line 2975, in _get_impl
    return db_load_fn(
  File "/home/airflow/.local/lib/python3.8/site-packages/sqlalchemy/orm/loading.py", line 530, in load_on_pk_identity
    session.execute(
  File "/home/airflow/.local/lib/python3.8/site-packages/sqlalchemy/orm/session.py", line 1716, in execute
    conn = self._connection_for_bind(bind)
  File "/home/airflow/.local/lib/python3.8/site-packages/sqlalchemy/orm/session.py", line 1555, in _connection_for_bind
    return self._transaction._connection_for_bind(
  File "/home/airflow/.local/lib/python3.8/site-packages/sqlalchemy/orm/session.py", line 750, in _connection_for_bind
    conn = bind.connect()
  File "/home/airflow/.local/lib/python3.8/site-packages/sqlalchemy/future/engine.py", line 406, in connect
    return super(Engine, self).connect()
  File "/home/airflow/.local/lib/python3.8/site-packages/sqlalchemy/engine/base.py", line 3325, in connect
    return self._connection_cls(self, close_with_result=close_with_result)
  File "/home/airflow/.local/lib/python3.8/site-packages/sqlalchemy/engine/base.py", line 96, in __init__
    else engine.raw_connection()
  File "/home/airflow/.local/lib/python3.8/site-packages/sqlalchemy/engine/base.py", line 3404, in raw_connection
    return self._wrap_pool_connect(self.pool.connect, _connection)
  File "/home/airflow/.local/lib/python3.8/site-packages/sqlalchemy/engine/base.py", line 3374, in _wrap_pool_connect
    Connection._handle_dbapi_exception_noconnection(
  File "/home/airflow/.local/lib/python3.8/site-packages/sqlalchemy/engine/base.py", line 2208, in _handle_dbapi_exception_noconnection
    util.raise_(
  File "/home/airflow/.local/lib/python3.8/site-packages/sqlalchemy/util/compat.py", line 211, in raise_
    raise exception
  File "/home/airflow/.local/lib/python3.8/site-packages/sqlalchemy/engine/base.py", line 3371, in _wrap_pool_connect
    return fn()
  File "/home/airflow/.local/lib/python3.8/site-packages/sqlalchemy/pool/base.py", line 327, in connect
    return _ConnectionFairy._checkout(self)
  File "/home/airflow/.local/lib/python3.8/site-packages/sqlalchemy/pool/base.py", line 894, in _checkout
    fairy = _ConnectionRecord.checkout(pool)
  File "/home/airflow/.local/lib/python3.8/site-packages/sqlalchemy/pool/base.py", line 493, in checkout
    rec = pool._do_get()
  File "/home/airflow/.local/lib/python3.8/site-packages/sqlalchemy/pool/impl.py", line 256, in _do_get
    return self._create_connection()
  File "/home/airflow/.local/lib/python3.8/site-packages/sqlalchemy/pool/base.py", line 273, in _create_connection
    return _ConnectionRecord(self)
  File "/home/airflow/.local/lib/python3.8/site-packages/sqlalchemy/pool/base.py", line 388, in __init__
    self.__connect()
  File "/home/airflow/.local/lib/python3.8/site-packages/sqlalchemy/pool/base.py", line 691, in __connect
    pool.logger.debug("Error on connect(): %s", e)
  File "/home/airflow/.local/lib/python3.8/site-packages/sqlalchemy/util/langhelpers.py", line 70, in __exit__
    compat.raise_(
  File "/home/airflow/.local/lib/python3.8/site-packages/sqlalchemy/util/compat.py", line 211, in raise_
    raise exception
  File "/home/airflow/.local/lib/python3.8/site-packages/sqlalchemy/pool/base.py", line 686, in __connect
    self.dbapi_connection = connection = pool._invoke_creator(self)
  File "/home/airflow/.local/lib/python3.8/site-packages/sqlalchemy/engine/create.py", line 574, in connect
    return dialect.connect(*cargs, **cparams)
  File "/home/airflow/.local/lib/python3.8/site-packages/sqlalchemy/engine/default.py", line 598, in connect
    return self.dbapi.connect(*cargs, **cparams)
  File "/home/airflow/.local/lib/python3.8/site-packages/psycopg2/__init__.py", line 122, in connect
    conn = _connect(dsn, connection_factory=connection_factory, **kwasync)
sqlalchemy.exc.OperationalError: (psycopg2.OperationalError) could not translate host name "postgres" to address: Temporary failure in name resolution

(Background on this error at: https://sqlalche.me/e/14/e3q8)
[2023-11-11T07:15:27.204+0000] {job.py:219} ERROR - Job heartbeat got an exception
Traceback (most recent call last):
  File "/home/airflow/.local/lib/python3.8/site-packages/sqlalchemy/engine/base.py", line 3371, in _wrap_pool_connect
    return fn()
  File "/home/airflow/.local/lib/python3.8/site-packages/sqlalchemy/pool/base.py", line 327, in connect
    return _ConnectionFairy._checkout(self)
  File "/home/airflow/.local/lib/python3.8/site-packages/sqlalchemy/pool/base.py", line 894, in _checkout
    fairy = _ConnectionRecord.checkout(pool)
  File "/home/airflow/.local/lib/python3.8/site-packages/sqlalchemy/pool/base.py", line 493, in checkout
    rec = pool._do_get()
  File "/home/airflow/.local/lib/python3.8/site-packages/sqlalchemy/pool/impl.py", line 256, in _do_get
    return self._create_connection()
  File "/home/airflow/.local/lib/python3.8/site-packages/sqlalchemy/pool/base.py", line 273, in _create_connection
    return _ConnectionRecord(self)
  File "/home/airflow/.local/lib/python3.8/site-packages/sqlalchemy/pool/base.py", line 388, in __init__
    self.__connect()
  File "/home/airflow/.local/lib/python3.8/site-packages/sqlalchemy/pool/base.py", line 691, in __connect
    pool.logger.debug("Error on connect(): %s", e)
  File "/home/airflow/.local/lib/python3.8/site-packages/sqlalchemy/util/langhelpers.py", line 70, in __exit__
    compat.raise_(
  File "/home/airflow/.local/lib/python3.8/site-packages/sqlalchemy/util/compat.py", line 211, in raise_
    raise exception
  File "/home/airflow/.local/lib/python3.8/site-packages/sqlalchemy/pool/base.py", line 686, in __connect
    self.dbapi_connection = connection = pool._invoke_creator(self)
  File "/home/airflow/.local/lib/python3.8/site-packages/sqlalchemy/engine/create.py", line 574, in connect
    return dialect.connect(*cargs, **cparams)
  File "/home/airflow/.local/lib/python3.8/site-packages/sqlalchemy/engine/default.py", line 598, in connect
    return self.dbapi.connect(*cargs, **cparams)
  File "/home/airflow/.local/lib/python3.8/site-packages/psycopg2/__init__.py", line 122, in connect
    conn = _connect(dsn, connection_factory=connection_factory, **kwasync)
psycopg2.OperationalError: could not translate host name "postgres" to address: Temporary failure in name resolution


The above exception was the direct cause of the following exception:

Traceback (most recent call last):
  File "/home/airflow/.local/lib/python3.8/site-packages/airflow/jobs/job.py", line 190, in heartbeat
    session.merge(self)
  File "/home/airflow/.local/lib/python3.8/site-packages/sqlalchemy/orm/session.py", line 3056, in merge
    return self._merge(
  File "/home/airflow/.local/lib/python3.8/site-packages/sqlalchemy/orm/session.py", line 3136, in _merge
    merged = self.get(
  File "/home/airflow/.local/lib/python3.8/site-packages/sqlalchemy/orm/session.py", line 2853, in get
    return self._get_impl(
  File "/home/airflow/.local/lib/python3.8/site-packages/sqlalchemy/orm/session.py", line 2975, in _get_impl
    return db_load_fn(
  File "/home/airflow/.local/lib/python3.8/site-packages/sqlalchemy/orm/loading.py", line 530, in load_on_pk_identity
    session.execute(
  File "/home/airflow/.local/lib/python3.8/site-packages/sqlalchemy/orm/session.py", line 1716, in execute
    conn = self._connection_for_bind(bind)
  File "/home/airflow/.local/lib/python3.8/site-packages/sqlalchemy/orm/session.py", line 1555, in _connection_for_bind
    return self._transaction._connection_for_bind(
  File "/home/airflow/.local/lib/python3.8/site-packages/sqlalchemy/orm/session.py", line 750, in _connection_for_bind
    conn = bind.connect()
  File "/home/airflow/.local/lib/python3.8/site-packages/sqlalchemy/future/engine.py", line 406, in connect
    return super(Engine, self).connect()
  File "/home/airflow/.local/lib/python3.8/site-packages/sqlalchemy/engine/base.py", line 3325, in connect
    return self._connection_cls(self, close_with_result=close_with_result)
  File "/home/airflow/.local/lib/python3.8/site-packages/sqlalchemy/engine/base.py", line 96, in __init__
    else engine.raw_connection()
  File "/home/airflow/.local/lib/python3.8/site-packages/sqlalchemy/engine/base.py", line 3404, in raw_connection
    return self._wrap_pool_connect(self.pool.connect, _connection)
  File "/home/airflow/.local/lib/python3.8/site-packages/sqlalchemy/engine/base.py", line 3374, in _wrap_pool_connect
    Connection._handle_dbapi_exception_noconnection(
  File "/home/airflow/.local/lib/python3.8/site-packages/sqlalchemy/engine/base.py", line 2208, in _handle_dbapi_exception_noconnection
    util.raise_(
  File "/home/airflow/.local/lib/python3.8/site-packages/sqlalchemy/util/compat.py", line 211, in raise_
    raise exception
  File "/home/airflow/.local/lib/python3.8/site-packages/sqlalchemy/engine/base.py", line 3371, in _wrap_pool_connect
    return fn()
  File "/home/airflow/.local/lib/python3.8/site-packages/sqlalchemy/pool/base.py", line 327, in connect
    return _ConnectionFairy._checkout(self)
  File "/home/airflow/.local/lib/python3.8/site-packages/sqlalchemy/pool/base.py", line 894, in _checkout
    fairy = _ConnectionRecord.checkout(pool)
  File "/home/airflow/.local/lib/python3.8/site-packages/sqlalchemy/pool/base.py", line 493, in checkout
    rec = pool._do_get()
  File "/home/airflow/.local/lib/python3.8/site-packages/sqlalchemy/pool/impl.py", line 256, in _do_get
    return self._create_connection()
  File "/home/airflow/.local/lib/python3.8/site-packages/sqlalchemy/pool/base.py", line 273, in _create_connection
    return _ConnectionRecord(self)
  File "/home/airflow/.local/lib/python3.8/site-packages/sqlalchemy/pool/base.py", line 388, in __init__
    self.__connect()
  File "/home/airflow/.local/lib/python3.8/site-packages/sqlalchemy/pool/base.py", line 691, in __connect
    pool.logger.debug("Error on connect(): %s", e)
  File "/home/airflow/.local/lib/python3.8/site-packages/sqlalchemy/util/langhelpers.py", line 70, in __exit__
    compat.raise_(
  File "/home/airflow/.local/lib/python3.8/site-packages/sqlalchemy/util/compat.py", line 211, in raise_
    raise exception
  File "/home/airflow/.local/lib/python3.8/site-packages/sqlalchemy/pool/base.py", line 686, in __connect
    self.dbapi_connection = connection = pool._invoke_creator(self)
  File "/home/airflow/.local/lib/python3.8/site-packages/sqlalchemy/engine/create.py", line 574, in connect
    return dialect.connect(*cargs, **cparams)
  File "/home/airflow/.local/lib/python3.8/site-packages/sqlalchemy/engine/default.py", line 598, in connect
    return self.dbapi.connect(*cargs, **cparams)
  File "/home/airflow/.local/lib/python3.8/site-packages/psycopg2/__init__.py", line 122, in connect
    conn = _connect(dsn, connection_factory=connection_factory, **kwasync)
sqlalchemy.exc.OperationalError: (psycopg2.OperationalError) could not translate host name "postgres" to address: Temporary failure in name resolution

(Background on this error at: https://sqlalche.me/e/14/e3q8)
[2023-11-11T07:15:43.953+0000] {job.py:219} ERROR - Job heartbeat got an exception
Traceback (most recent call last):
  File "/home/airflow/.local/lib/python3.8/site-packages/sqlalchemy/engine/base.py", line 3371, in _wrap_pool_connect
    return fn()
  File "/home/airflow/.local/lib/python3.8/site-packages/sqlalchemy/pool/base.py", line 327, in connect
    return _ConnectionFairy._checkout(self)
  File "/home/airflow/.local/lib/python3.8/site-packages/sqlalchemy/pool/base.py", line 894, in _checkout
    fairy = _ConnectionRecord.checkout(pool)
  File "/home/airflow/.local/lib/python3.8/site-packages/sqlalchemy/pool/base.py", line 493, in checkout
    rec = pool._do_get()
  File "/home/airflow/.local/lib/python3.8/site-packages/sqlalchemy/pool/impl.py", line 256, in _do_get
    return self._create_connection()
  File "/home/airflow/.local/lib/python3.8/site-packages/sqlalchemy/pool/base.py", line 273, in _create_connection
    return _ConnectionRecord(self)
  File "/home/airflow/.local/lib/python3.8/site-packages/sqlalchemy/pool/base.py", line 388, in __init__
    self.__connect()
  File "/home/airflow/.local/lib/python3.8/site-packages/sqlalchemy/pool/base.py", line 691, in __connect
    pool.logger.debug("Error on connect(): %s", e)
  File "/home/airflow/.local/lib/python3.8/site-packages/sqlalchemy/util/langhelpers.py", line 70, in __exit__
    compat.raise_(
  File "/home/airflow/.local/lib/python3.8/site-packages/sqlalchemy/util/compat.py", line 211, in raise_
    raise exception
  File "/home/airflow/.local/lib/python3.8/site-packages/sqlalchemy/pool/base.py", line 686, in __connect
    self.dbapi_connection = connection = pool._invoke_creator(self)
  File "/home/airflow/.local/lib/python3.8/site-packages/sqlalchemy/engine/create.py", line 574, in connect
    return dialect.connect(*cargs, **cparams)
  File "/home/airflow/.local/lib/python3.8/site-packages/sqlalchemy/engine/default.py", line 598, in connect
    return self.dbapi.connect(*cargs, **cparams)
  File "/home/airflow/.local/lib/python3.8/site-packages/psycopg2/__init__.py", line 122, in connect
    conn = _connect(dsn, connection_factory=connection_factory, **kwasync)
psycopg2.OperationalError: could not translate host name "postgres" to address: Temporary failure in name resolution


The above exception was the direct cause of the following exception:

Traceback (most recent call last):
  File "/home/airflow/.local/lib/python3.8/site-packages/airflow/jobs/job.py", line 190, in heartbeat
    session.merge(self)
  File "/home/airflow/.local/lib/python3.8/site-packages/sqlalchemy/orm/session.py", line 3056, in merge
    return self._merge(
  File "/home/airflow/.local/lib/python3.8/site-packages/sqlalchemy/orm/session.py", line 3136, in _merge
    merged = self.get(
  File "/home/airflow/.local/lib/python3.8/site-packages/sqlalchemy/orm/session.py", line 2853, in get
    return self._get_impl(
  File "/home/airflow/.local/lib/python3.8/site-packages/sqlalchemy/orm/session.py", line 2975, in _get_impl
    return db_load_fn(
  File "/home/airflow/.local/lib/python3.8/site-packages/sqlalchemy/orm/loading.py", line 530, in load_on_pk_identity
    session.execute(
  File "/home/airflow/.local/lib/python3.8/site-packages/sqlalchemy/orm/session.py", line 1716, in execute
    conn = self._connection_for_bind(bind)
  File "/home/airflow/.local/lib/python3.8/site-packages/sqlalchemy/orm/session.py", line 1555, in _connection_for_bind
    return self._transaction._connection_for_bind(
  File "/home/airflow/.local/lib/python3.8/site-packages/sqlalchemy/orm/session.py", line 750, in _connection_for_bind
    conn = bind.connect()
  File "/home/airflow/.local/lib/python3.8/site-packages/sqlalchemy/future/engine.py", line 406, in connect
    return super(Engine, self).connect()
  File "/home/airflow/.local/lib/python3.8/site-packages/sqlalchemy/engine/base.py", line 3325, in connect
    return self._connection_cls(self, close_with_result=close_with_result)
  File "/home/airflow/.local/lib/python3.8/site-packages/sqlalchemy/engine/base.py", line 96, in __init__
    else engine.raw_connection()
  File "/home/airflow/.local/lib/python3.8/site-packages/sqlalchemy/engine/base.py", line 3404, in raw_connection
    return self._wrap_pool_connect(self.pool.connect, _connection)
  File "/home/airflow/.local/lib/python3.8/site-packages/sqlalchemy/engine/base.py", line 3374, in _wrap_pool_connect
    Connection._handle_dbapi_exception_noconnection(
  File "/home/airflow/.local/lib/python3.8/site-packages/sqlalchemy/engine/base.py", line 2208, in _handle_dbapi_exception_noconnection
    util.raise_(
  File "/home/airflow/.local/lib/python3.8/site-packages/sqlalchemy/util/compat.py", line 211, in raise_
    raise exception
  File "/home/airflow/.local/lib/python3.8/site-packages/sqlalchemy/engine/base.py", line 3371, in _wrap_pool_connect
    return fn()
  File "/home/airflow/.local/lib/python3.8/site-packages/sqlalchemy/pool/base.py", line 327, in connect
    return _ConnectionFairy._checkout(self)
  File "/home/airflow/.local/lib/python3.8/site-packages/sqlalchemy/pool/base.py", line 894, in _checkout
    fairy = _ConnectionRecord.checkout(pool)
  File "/home/airflow/.local/lib/python3.8/site-packages/sqlalchemy/pool/base.py", line 493, in checkout
    rec = pool._do_get()
  File "/home/airflow/.local/lib/python3.8/site-packages/sqlalchemy/pool/impl.py", line 256, in _do_get
    return self._create_connection()
  File "/home/airflow/.local/lib/python3.8/site-packages/sqlalchemy/pool/base.py", line 273, in _create_connection
    return _ConnectionRecord(self)
  File "/home/airflow/.local/lib/python3.8/site-packages/sqlalchemy/pool/base.py", line 388, in __init__
    self.__connect()
  File "/home/airflow/.local/lib/python3.8/site-packages/sqlalchemy/pool/base.py", line 691, in __connect
    pool.logger.debug("Error on connect(): %s", e)
  File "/home/airflow/.local/lib/python3.8/site-packages/sqlalchemy/util/langhelpers.py", line 70, in __exit__
    compat.raise_(
  File "/home/airflow/.local/lib/python3.8/site-packages/sqlalchemy/util/compat.py", line 211, in raise_
    raise exception
  File "/home/airflow/.local/lib/python3.8/site-packages/sqlalchemy/pool/base.py", line 686, in __connect
    self.dbapi_connection = connection = pool._invoke_creator(self)
  File "/home/airflow/.local/lib/python3.8/site-packages/sqlalchemy/engine/create.py", line 574, in connect
    return dialect.connect(*cargs, **cparams)
  File "/home/airflow/.local/lib/python3.8/site-packages/sqlalchemy/engine/default.py", line 598, in connect
    return self.dbapi.connect(*cargs, **cparams)
  File "/home/airflow/.local/lib/python3.8/site-packages/psycopg2/__init__.py", line 122, in connect
    conn = _connect(dsn, connection_factory=connection_factory, **kwasync)
sqlalchemy.exc.OperationalError: (psycopg2.OperationalError) could not translate host name "postgres" to address: Temporary failure in name resolution

(Background on this error at: https://sqlalche.me/e/14/e3q8)
[2023-11-11T07:16:05.142+0000] {local_task_job_runner.py:115} ERROR - Received SIGTERM. Terminating subprocesses
[2023-11-11T07:16:05.257+0000] {process_utils.py:131} INFO - Sending 15 to group 251. PIDs of all processes in the group: [251]
[2023-11-11T07:16:05.319+0000] {process_utils.py:86} INFO - Sending the signal 15 to group 251
[2023-11-11T07:16:05.412+0000] {taskinstance.py:1632} ERROR - Received SIGTERM. Terminating subprocesses.
[2023-11-11T07:16:07.100+0000] {taskinstance.py:1937} ERROR - Task failed with exception
Traceback (most recent call last):
  File "/home/airflow/.local/lib/python3.8/site-packages/airflow/operators/python.py", line 192, in execute
    return_value = self.execute_callable()
  File "/home/airflow/.local/lib/python3.8/site-packages/airflow/operators/python.py", line 209, in execute_callable
    return self.python_callable(*self.op_args, **self.op_kwargs)
  File "/opt/airflow/dags/src/datapreprocessing.py", line 30, in split_dataset
    X_test.to_csv(os.path.join(os.path.dirname(__file__), "../data/X_test.csv"), index=False)
  File "/home/airflow/.local/lib/python3.8/site-packages/pandas/core/generic.py", line 3772, in to_csv
    return DataFrameRenderer(formatter).to_csv(
  File "/home/airflow/.local/lib/python3.8/site-packages/pandas/io/formats/format.py", line 1186, in to_csv
    csv_formatter.save()
  File "/home/airflow/.local/lib/python3.8/site-packages/pandas/io/formats/csvs.py", line 259, in save
    self._save()
  File "/home/airflow/.local/lib/python3.8/site-packages/pandas/io/formats/csvs.py", line 264, in _save
    self._save_body()
  File "/home/airflow/.local/lib/python3.8/site-packages/pandas/io/formats/csvs.py", line 302, in _save_body
    self._save_chunk(start_i, end_i)
  File "/home/airflow/.local/lib/python3.8/site-packages/pandas/io/formats/csvs.py", line 313, in _save_chunk
    libwriters.write_csv_rows(
  File "pandas/_libs/writers.pyx", line 72, in pandas._libs.writers.write_csv_rows
  File "/home/airflow/.local/lib/python3.8/site-packages/airflow/models/taskinstance.py", line 1634, in signal_handler
    raise AirflowException("Task received SIGTERM signal")
airflow.exceptions.AirflowException: Task received SIGTERM signal
[2023-11-11T07:16:08.095+0000] {taskinstance.py:1400} INFO - Marking task as UP_FOR_RETRY. dag_id=preprocessing_v1, task_id=split_task, execution_date=20231110T000000, start_date=20231111T071435, end_date=20231111T071608
[2023-11-11T07:16:08.356+0000] {standard_task_runner.py:104} ERROR - Failed to execute job 4 for task split_task (Task received SIGTERM signal; 251)
[2023-11-11T07:16:08.781+0000] {process_utils.py:79} INFO - Process psutil.Process(pid=251, status='terminated', exitcode=1, started='07:14:34') (251) terminated with exit code 1
[2023-11-11T07:16:10.062+0000] {local_task_job_runner.py:228} INFO - Task exited with return code 143
[2023-11-11T07:16:10.611+0000] {taskinstance.py:2778} INFO - 0 downstream tasks scheduled from follow-on schedule check
[2023-11-11T07:17:53.210+0000] {taskinstance.py:1159} INFO - Dependencies all met for dep_context=non-requeueable deps ti=<TaskInstance: preprocessing_v1.split_task scheduled__2023-11-10T00:00:00+00:00 [queued]>
[2023-11-11T07:17:53.225+0000] {taskinstance.py:1159} INFO - Dependencies all met for dep_context=requeueable deps ti=<TaskInstance: preprocessing_v1.split_task scheduled__2023-11-10T00:00:00+00:00 [queued]>
[2023-11-11T07:17:53.227+0000] {taskinstance.py:1361} INFO - Starting attempt 1 of 6
[2023-11-11T07:17:53.244+0000] {taskinstance.py:1382} INFO - Executing <Task(PythonOperator): split_task> on 2023-11-10 00:00:00+00:00
[2023-11-11T07:17:53.256+0000] {standard_task_runner.py:57} INFO - Started process 254 to run task
[2023-11-11T07:17:53.261+0000] {standard_task_runner.py:84} INFO - Running: ['***', 'tasks', 'run', 'preprocessing_v1', 'split_task', 'scheduled__2023-11-10T00:00:00+00:00', '--job-id', '6', '--raw', '--subdir', 'DAGS_FOLDER/***_code.py', '--cfg-path', '/tmp/tmpnha74uqs']
[2023-11-11T07:17:53.269+0000] {standard_task_runner.py:85} INFO - Job 6: Subtask split_task
[2023-11-11T07:17:53.334+0000] {task_command.py:416} INFO - Running <TaskInstance: preprocessing_v1.split_task scheduled__2023-11-10T00:00:00+00:00 [running]> on host 2c83865699e0
[2023-11-11T07:17:53.411+0000] {taskinstance.py:1662} INFO - Exporting env vars: AIRFLOW_CTX_DAG_OWNER='Team 3' AIRFLOW_CTX_DAG_ID='preprocessing_v1' AIRFLOW_CTX_TASK_ID='split_task' AIRFLOW_CTX_EXECUTION_DATE='2023-11-10T00:00:00+00:00' AIRFLOW_CTX_TRY_NUMBER='1' AIRFLOW_CTX_DAG_RUN_ID='scheduled__2023-11-10T00:00:00+00:00'
[2023-11-11T07:17:56.833+0000] {python.py:194} INFO - Done. Returned value was: 1
[2023-11-11T07:17:56.904+0000] {taskinstance.py:1400} INFO - Marking task as SUCCESS. dag_id=preprocessing_v1, task_id=split_task, execution_date=20231110T000000, start_date=20231111T071753, end_date=20231111T071756
[2023-11-11T07:17:56.954+0000] {local_task_job_runner.py:228} INFO - Task exited with return code 0
[2023-11-11T07:17:57.073+0000] {taskinstance.py:2778} INFO - 0 downstream tasks scheduled from follow-on schedule check
